Workbook
Name afra_scale: Table1[#All]

Sheet SoH
B2: vessel_name | C2: controller | D2: loading_port | E2: entered_soh | F2: loading_date | G2: grade | H2: last_seen(days) | I2: exited_soh | J2: in/out | K2: discharged | L2: last_loading_state | M2: Quantity | N2: Notes | P2: checked today? | U2: timestamp
B3: KARAN | C3: Bahri | D3: Ras Tanura | E3: 46196 | F3: 46199 | G3: Arab Heavy | I3: 46205 | J3: out | L3: laden | M3: VLCC | X3: NOT LOADED - INSIDE
B4: ZAYNAH | C4: Bahri | D4: Ras Tanura | E4: 46196 | F4: 46198 | G4: Arab | I4: 46202 | J4: out | L4: laden | M4: VLCC | X4: SCHEDULED TO LOAD - OUTSIDE
B5: NISSOS HERACLEA | C5: Kyklades | D5: Al Basrah | E5: 46196 | F5: 46197 | G5: Basrah | I5: 46202 | J5: re-entered for another loading | K5: Sohar Light | M5: VLCC | X5: LOADED - INSIDE | AI5: 42 | AJ5: 31
B6: NISSOS KEA | C6: Kyklades | D6: Halul Island | I6: 46202 | J6: re-entered for another loading | M6: VLCC | X6: MANAGE TO EXIT | AI6: 45 | AJ6: 32
B7: QASBA | C7: Bahri | D7: Ras Tanura | E7: 46196 | F7: 46200 | G7: Arab | I7: 46205 | J7: out | L7: laden | M7: VLCC | X7: STRUCK | AI7: 11 | AJ7: 8
B8: AMAD | C8: Bahri | D8: Ras Tanura | E8: 46196 | F8: 46198 | G8: Arab | I8: 46205 | J8: out | L8: laden | M8: VLCC | X8: HAVEN'T SEEN IN A WHILE | Y8: Italics | AI8: 18 | AJ8: 9
B9: MANIFA | C9: Bahri | D9: Ras Tanura | F9: 46200 | G9: Arab | I9: 46205 | J9: out | L9: laden | M9: VLCC | AI9: =SUM(AI5:AI8) -> 116 | AJ9: =SUM(AJ5:AJ8) -> 80
B10: BASRAH ENERGY | C10: ADNOC | H10: 30 | J10: in | L10: laden | M10: 800 kb | P10: x | Q10: Floating, no more info | X10: OUTSIDE
B11: DAS | C11: NAVIG8 ASIA PTE LTD | D11: Zirku Island | E11: 46199 | F11: 46200 | G11: Zakum | H11: 6 | I11: 46202 | J11: re-entered for another loading | L11: laden | M11: 2 mb
B12: ANGOLA B | C12: ADNOC | D12: Das Island | E12: 46199 | F12: 46200 | G12: Das | H12: 12 | I12: 46204 | J12: re-entered for another loading | L12: laden | M12: 2 mb
A13: struck | B13: AL BAHYAH | C13: NAVIG8 ASIA PTE LTD | D13: Zirku Island | E13: 46201 | F13: 46202 | G13: Zakum | H13: 6 | I13: 46204 | J13: out | K13: Fujairah | L13: ballast | M13: VLCC
B14: FRANCE C | C14: ADNOC | D14: Das Island | E14: 46200 | F14: 46201 | G14: Das | H14: 12 | I14: 46204 | J14: out | L14: laden | M14: 1.5 mb
B15: JALADI | C15: Bahri | D15: Ras Tanura | E15: 46201 | F15: 46203 | G15: Arab | I15: 46206 | J15: out | L15: laden | M15: 2 mb
B16: NISSOS TIGANI | C16: ETC | D16: Al Basrah | E16: 46198 | F16: 46202 | G16: Basrah | I16: 46207 | J16: out | K16: Ain Sukhna | L16: laden | M16: 1 mb
B17: AL RIQQA | C17: KPC | D17: Mina Al-Ahmadi | F17: 46188 | G17: Kuwait | H17: 60 | J17: in | L17: laden | M17: 2 mb | P17: x
B18: DAR SALWA | C18: KPC | D18: Mina Al-Ahmadi | F18: 46203 | G18: Kuwait | H18: 60 | J18: in | L18: laden | M18: 2 mb | P18: x
B19: GRAND LADY | C19: Eastmed | D19: Al Basrah | F19: 46203 | G19: Basrah | H19: 60 | J19: in | L19: ballast | M19: VLCC | P19: x
B20: HAFEET | C20: NAVIG8 ASIA PTE LTD | D20: Umm Lulu | F20: 46204 | G20: Umm Lulu | H20: 8 | I20: 46208 | J20: out | K20: Khor | L20: laden | M20: 2 mb
A21: struck | B21: MOMBASA B | C21: Sinokor | D21: Zirku Island | F21: 46203 | G21: Zakum | H21: 10 | I21: 46206 | J21: out | K21: Fujairah | L21: laden | M21: 2 mb | R21: ADNOC
B22: DAR SALWA | C22: KPC | D22: Mina Al-Ahmadi | F22: 46203 | G22: Kuwait | H22: 30 | J22: ? | K22: Sohar Light | L22: laden | M22: 2 mb
B23: NISALAH | C23: Bahri | D23: Ras Tanura | F23: 46203 | G23: Arab | I23: 46206 | J23: out | K23: Okinawa | L23: laden | M23: 2 mb
B24: UQAB | C24: Sinopec | D24: Juaymah | E24: 46200 | F24: 46203 | G24: Arab | I24: 46207 | J24: out | K24: Okinawa | L24: laden | M24: 2 mb
B25: BAHRAIN PROSPERITY | C25: ADNOC | D25: Zirku Island | F25: 46209 | G25: Zakum | H25: 3 | I25: 46213 | J25: out | K25: Fujairah | L25: laden | M25: 2 mb
B26: AL JABRIYAH II | C26: KPC | D26: Mina Al-Ahmadi | F26: 46204 | G26: Kuwait | H26: 60 | J26: ? | K26: Sohar Light | L26: ballast | M26: VLCC
B27: SINGAPORE LOYALTY | C27: ZhenHua Oil | D27: Al Basrah | F27: 46201 | G27: Basrah | H27: 21 | J27: in | K27: Yantai | L27: laden | M27: 2 mb | P27: x
B28: ARGENTINA B | C28: Sinokor | D28: Das Island | E28: 46202 | F28: 46204 | G28: Das | I28: 46208 | J28: re-entered for another loading | K28: Khor | L28: ballast | M28: VLCC | R28: ADNOC
B29: CAMEROON PROSPERITY | C29: PTT | D29: Zirku island | E29: 46206 | F29: 46207 | G29: Zakum | H29: 1 | J29: in | L29: laden | M29: 2 mb | P29: x | R29: Prevously loaded and transfer at
B30: AL FUNTAS | C30: Kuwait Energy | D30: Mina Al-Ahmadi | G30: Kuwait | H30: 60 | I30: 46210 | J30: ? | K30: Sohar Light | L30: ballast | M30: VLCC
B31: CYPRUS PROSPERITY | C31: ADNOC | D31: Das Island | F31: 46207 | G31: Das | I31: 46210 | J31: out | K31: Fujairah | L31: ballast | M31: VLCC | AH31: =12.5*4 -> 50
B32: DAS | C32: NAVIG8 ASIA PTE LTD | D32: Zirku Island | F32: 46207 | G32: Zakum | H32: 6 | I32: 46202 | J32: out | K32: Fujairah | L32: laden | M32: 2 mb | AH32: 45.39
B33: LILA VADINAR | C33: IOC | D33: Mina Al-Ahmadi | F33: 46207 | G33: Kuwait | I33: 46212 | J33: out | K33: Sohar Light | L33: ballast | M33: VLCC | AH33: =+AH31-AH32 -> 4.61
B34: NISSOS HERACLEA | C34: Kyklades | D34: FSO Qatar Petroleum Al Shaheen | E34: 46207 | F34: 46208 | G34: Shaheen | I34: 46213 | J34: out | K34: Sohar Light | L34: ballast | M34: VLCC
B35: BELGIUM B | C35: Sinokor | D35: Juaymah | E35: 46195 | F35: 46209 | G35: Arab | H35: 5 | I35: 46214 | J35: out | L35: laden | M35: 2 mb
B36: BAHRAIN PROSPERITY | C36: Sinokor | D36: Zirku Island | F36: 46209 | G36: Zakum | H36: 3 | I36: 46214 | J36: out | K36: Fujairah | L36: laden | M36: 2 mb
B37: DOMINICA PROSPERITY | C37: Sinokor | D37: Ras Tanura | F37: 46211 | G37: Arab | H37: 24 | J37: in | L37: laden | M37: 2 mb | P37: x | R37: ADNOC
B38: BARBADOS PROSPERITY | C38: Sinokor | D38: Al Basrah | F38: 46207 | G38: Basrah | H38: 1 | J38: in | L38: laden | M38: 2 mb | P38: x
B39: SANAM | C39: Bahri | D39: Juaymah | E39: 46210 | F39: 46211 | G39: Arab | H39: 30 | J39: in | L39: laden | M39: 2 mb | P39: x | R39: Trafigura
R40: Mercuria | T40: localtion shows
B41: EGYPT PROSPERITY | C41: Sinokor | D41: Al Basrah | F41: 46211 | G41: Basrah | H41: 24 | J41: in | L41: laden | M41: 2 mb | P41: x
...

Sheet bab
B3: vessel_name | C3: controller | D3: loading_port | E3: direction | F3: loading_date | G3: grade | H3: last_seen(days) | I3: exited | J3: in/out | K3: discharged | L3: last_loading_state | M3: Quantity (kb) | N3: cycle_completed | O3: Track | P3: Notes | Q3: destination_country
B4: SOPHIA | C4: Maran Tankers Management | D4: Muajjiz | E4: Bab | F4: 46220 | G4: Arab | H4: 6 | J4: in | L4: laden | M4: 2000 | S4: x
B5: AMAZON | C5: IOC | D5: Muajjiz | E5: Suez | F5: 46223 | G5: Arab | H5: 2 | J5: in | K5: Chennai | L5: laden | M5: 1000 | O5: y | Q5: China
B6: RODOS | C6: Mangalore Refinery and Petrochemicals Ltd | D6: Muajjiz | E6: Bab | F6: 46223 | G6: Arab | H6: 5 | J6: in | K6: Mangalore | L6: laden | M6: 775 | O6: y | Q6: India
B7: DHT MUSTANG | C7: DHT Norway | D7: Muajjiz | E7: ? | F7: 46224 | G7: Arab | J7: in | L7: laden | M7: 2000 | O7: y | P7: did route change?
B8: COSLUCKY LAKE | C8: COSCO | D8: Yanbu Crude | E8: ? | F8: 46232 | G8: Arab | J8: in | L8: ballast | M8: VLCC | O8: y | P8: At berth (22-07-2026)
B9: FPMC C LORD | C9: Formosa Plastic Group | D9: Yanbu Crude | E9: ? | F9: 46226 | G9: Arab | J9: in | L9: ballast | M9: VLCC
B10: KHUZAMA | C10: Bahri | D10: Yanbu Crude | E10: ? | F10: 46230 | G10: Arab | J10: in | L10: ballast | M10: VLCC
B11: XIN WEI YANG | C11: COSCO | D11: Yanbu Crude | E11: ? | F11: 46227 | G11: Arab | J11: in | K11: Eastern Asia | L11: ballast | M11: VLCC
B12: NEW DISCOVERY | C12: New Shipping Ltd | D12: Yanbu Crude | E12: ? | F12: 46228 | G12: Arab | H12: 2 | J12: in | L12: ballast | M12: VLCC | O12: y | Q12: China
B15: NEW CHAMPION | C15: Sinopec | D15: Yanbu Crude | E15: Bab | F15: 46227 | G15: Arab | J15: out | K15: China | L15: ballast | M15: VLCC
B16: NEW PRIME | C16: Sinopec | D16: Yanbu Crude | E16: Bab | F16: 46229 | G16: Arab | J16: out | K16: China | L16: ballast | M16: VLCC
B17: C INNOVATOR | C17: LMCS | D17: Yanbu Crude | E17: Bab | F17: 46226 | G17: Arab | J17: out | L17: laden | M17: VLCC | O17: y | P17: scehduled outside | Q17: China
B18: VI PIONEER | C18: Exxon | D18: Yanbu Crude | E18: ? | F18: 46227 | G18: Arab | J18: out | K18: Eastern Asia | L18: ballast | M18: VLCC | O18: y | P18: scehduled outside | Q18: India
B19: LAYNAH | C19: ? | D19: Yanbu Crude | E19: Bab | F19: 46228 | G19: Arab | H19: 3 | J19: out | L19: ballast | M19: VLCC | O19: y | P19: scehduled outside
B20: KAHLA | C20: Bahri | D20: Yanbu Crude | E20: Bab | F20: 46228 | G20: Arab | H20: 3 | J20: out | L20: ballast | M20: VLCC | O20: Y | P20: scehduled outside
B21: SAHBA | C21: Bahri | D21: Yanbu Crude | E21: Bab | F21: 46228 | G21: Arab | H21: 2 | J21: out | L21: ballast | M21: VLCC | O21: Y | P21: scehduled outside
B22: P ALIKI | C22: Maersk | D22: Yanbu Crude | E22: Bab | F22: 46229 | G22: Arab | J22: out | L22: ballast | M22: VLCC | O22: Y | P22: scehduled outside
B23: XIN TONG YANG | C23: COSCO | D23: Yanbu Crude | E23: Bab | F23: 46245 | G23: Arab | J23: out | K23: China | L23: ballast | M23: VLCC | O23: y | Q23: China
O24: Y | P24: scehduled outside
B25: vessel_name | C25: controller | D25: loading_port | E25: direction | F25: loading_date | G25: grade | H25: last_seen(days) | I25: exited | J25: in/out | K25: discharged | L25: last_loading_state | M25: Quantity (kb) | N25: cycle_completed | O25: Track | P25: Notes | Q25: destination_country
B26: COSNEW LAKE | C26: Sinopec | D26: Yanbu Crude | E26: Bab | F26: 46221 | G26: Arab | I26: 46226 | J26: out | K26: Huizhou | L26: laden | M26: 2000 | N26: x
B27: XIN LONG YANG | C27: Sinopec | D27: Yanbu Crude | E27: Bab | F27: 46221 | G27: Arab | I27: 46226 | J27: out | K27: Qinzhou | L27: laden | M27: 2000 | N27: x | O27: y | Q27: China
B28: LAHORE | C28: PNSC | D28: Muajjiz | E28: Bab | F28: 46222 | G28: Arab | I28: 46229 | J28: out | K28: Karachi | L28: laden | M28: 750 | N28: x | O28: y | Q28: Pakistan | S28: x
B29: NEW EXPLORER | C29: Sinopec | D29: Yanbu Crude | E29: Bab | F29: 46223 | G29: Arab | I29: 46229 | J29: out | K29: Ningbo | L29: laden | M29: 2000 | N29: x
B30: NEW PEARL | C30: AMCL | D30: Yanbu Crude | E30: Bab | F30: 46228 | G30: Arab | I30: 46230 | J30: out | K30: China | L30: laden | M30: 2000
B31: KARACHI | C31: PNSC | D31: Yanbu Crude | E31: Bab | F31: 46225 | G31: Arab | I31: 46231 | J31: out | K31: Pakistan | L31: laden | M31: 750 | N31: x
B32: DESH VAIBHAV | C32: SCI | D32: Yanbu Crude | E32: Bab | F32: 46226 | G32: Arab | I32: 46235 | J32: in | K32: Sika | L32: laden | M32: 2000 | N32: x | O32: y | P32: At berth (24-07-2026) | Q32: India
B33: LESVOS | D33: Yanbu Crude | E33: Bab | F33: 46229 | G33: Arab | I33: 46236 | J33: out | K33: ? | L33: laden | M33: 1000 | N33: x
Q37: Total Inside | R37: =+COUNTIFS(J:J,"in",$N:$N,"") -> 10
Q38: Total outside | R38: =+COUNTIFS(J:J,"out") -> 25
Q39: Total | R39: =+R37+R38 -> 35
B41: FRONT GAULA | C41: ? | D41: Yanbu Crude | E41: Suez | F41: 46220 | G41: Arab | J41: out | K41: Ain Sokhna | L41: laden | M41: 1000 | N41: x | Q41: Egypt
B42: AMZAN | D42: Muajjiz | E42: Suez | F42: 46222 | G42: Arab | J42: out | K42: Ain Sokhna | L42: ballast | M42: VLCC | N42: x | Q42: Egypt
B43: FARHAH | D43: Muajjiz | E43: Suez | F43: 46222 | G43: Arab | J43: out | L43: laden | M43: 2000 | N43: x
B44: MINEMIA | C44: Marine Trust | D44: Muajjiz | E44: Suez | F44: 46225 | G44: Arab | J44: out | L44: laden | M44: 770 | O44: y | P44: At berth (22-07-2026)
B45: DHT PUMA | C45: DHT Norway | D45: Yanbu Crude | E45: Suez | F45: 46229 | G45: Arab | J45: in | K45: Ain Sokhna | L45: laden | M45: 2000
B46: DHT GAZELLE | C46: DHT Norway | D46: Yanbu Crude | E46: Suez | F46: 46226 | G46: Arab | J46: out | K46: Batan | L46: laden | M46: 1000 | O46: y | P46: entered with transponder off | Q46: Philippines
B47: OLYMPIC LUCK | C47: Olympic Shipping | D47: Yanbu Crude | E47: Suez | F47: 46227 | G47: Arab | J47: out | K47: Eastern Asia | L47: laden | M47: 1200
B49: DESH VISHAL | C49: SCI | D49: Yanbu Crude | E49: Bab | F49: 46226 | G49: Arab | J49: out | K49: Sikka | L49: ballast | M49: VLCC | O49: y | P49: scehduled outside | Q49: China
...

Sheet Sheet2
D7: Vessel | E7: Capacity (bbl) | F7: location_approx | G7: last_loading_state | H7: last_seen(days)
D8: New Amorgos | E8: 761476 | F8: Off Al-bashra | G8: ballast
D9: New Andros | E9: 2120654 | F9: Off fujairah | G9: ballast
D10: New Dynasty | E10: 2102231 | F10: Off Al-bashra | G10: laden
D11: New Giant | E11: 2165192 | F11: Off siri island | G11: ballast | I11: indicating Al Bashrah
C12: inactive | D12: New Diamond | E12: 2043081 | F12: ? | G12: ballast | H12: =2*30 -> 60
D13: New Friendship | E13: 712724 | F13: Off Gibraltar | G13: ballast
C14: inactive | D14: Cape Balder | E14: 1053738 | F14: ? | G14: ballast | H14: =4*30 -> 120
C15: inactive | D15: New Inspiration | E15: 2034666 | F15: ? | G15: ballast | H15: =2*30 -> 60
D16: New Legend | E16: 1053738 | F16: Reaching Suez Canal | G16: ballast
C17: inactive | D17: New Paros | E17: 733914 | F17: ? | G17: ? | H17: =5*365 -> 1825
D18: New Vision | E18: 1074168 | F18: Off the coast of wales | G18: laden
D19: Paros | E19: 729536 | F19: Off ust luga | G19: ballast
C20: inactive | D20: Star I | E20: 773986 | F20: ? | G20: ? | H20: =4*365 -> 1460
D21: Tinagu | E21: 2102231 | F21: ? | G21: ballast | H21: =6*30 -> 180
D22: Trident Hope | E22: 712692 | F22: Off malasya coast | G22: laden

Sheet Sheet1
A5: =+I5 -> Crossing Date | B5: Side | C5: size | D5: Products | E5: Vessel Name | F5: IMO | G5: Flag Name | H5: Direction | I5: Crossing Date | J5: Crossing Type | K5: Loading State | L5: Cargo Type | M5: Quantity | N5: Quantity Unit | O5: Last Cargo Zone | P5: Last Cargo Country | Q5: Next Port | R5: Next Port Country | S5: Deadweight | T5: Build Year | U5: Build Country | V5: dwt_kdwt | W5: afra_class | X5: cargo_group | Y5: cargo_source | Z5: volume_bbl | AA5: sanctioned_iran | AB5: sanctioned_sdn | AC5: sanctioned_any | AD5: is_dark_route | AE5: is_dark_fleet | AF5: fleet
A6: =+I6 -> 46222 | B6: =+H6 -> Entered MEG | C6: 500 kb | D6: dark activity | E6: ARGO MARIS | F6: 9041643 | G6: CURACAO | H6: Entered MEG | I6: 46222 | J6: Iranian Route | K6: Ballast | L6: NaN | M6: 0 | N6: bbl | O6: Fujairah Light. | P6: United Arab Emirates | Q6: NaN | R6: NaN | S6: 1229 | T6: 1991 | U6: JAPAN | V6: 1.229 | W6: Below GP | X6: ballast | Y6: loading_state | Z6: 0 | AA6: FALSE | AB6: FALSE | AC6: FALSE | AD6: FALSE | AE6: FALSE | AF6: clean fleet
A7: =+I7 -> 46222 | B7: =+H7 -> Entered MEG | C7: 500 kb | D7: Fuel oil | E7: KAVOMALEAS | F7: 1042823 | G7: MALTA | H7: Entered MEG | I7: 46222 | J7: Omani Route | K7: Ballast | L7: NaN | M7: 0 | N7: bbl | O7: Fujairah | P7: United Arab Emirates | Q7: Mideast Gulf | R7: NaN | S7: 74978 | T7: 2025 | U7: CHINA | V7: 74.978 | W7: LR1 | X7: ballast | Y7: loading_state | Z7: 0 | AA7: FALSE | AB7: FALSE | AC7: FALSE | AD7: FALSE | AE7: FALSE | AF7: clean fleet
A8: =+I8 -> 46222 | B8: =+H8 -> Exited MEG | C8: 300 kb | D8: dark activity | E8: MADESTAR | F8: 9289726 | G8: PANAMA | H8: Exited MEG | I8: 46222 | J8: Dark/Unknown Route | K8: Ballast | L8: NaN | M8: 0 | N8: bbl | O8: Lanqiao | P8: China | Q8: NaN | R8: NaN | S8: 319180 | T8: 2005 | U8: REPUBLIC OF KOREA | V8: 319.18 | W8: VLCC | X8: ballast | Y8: loading_state | Z8: 0 | AA8: TRUE | AB8: TRUE | AC8: TRUE | AD8: TRUE | AE8: TRUE | AF8: dark fleet
A9: =+I9 -> 46222 | B9: =+H9 -> Exited MEG | C9: 300 kb | D9: dark activity | E9: YOKO 1 | F9: 9241085 | G9: PANAMA | H9: Exited MEG | I9: 46222 | J9: Iranian Route | K9: Ballast | L9: NaN | M9: 0 | N9: bbl | O9: Hamriya | P9: United Arab Emirates | Q9: Oman | R9: Oman | S9: 46684 | T9: 2004 | U9: CROATIA | V9: 46.684 | W9: LR1 | X9: ballast | Y9: loading_state | Z9: 0 | AA9: FALSE | AB9: FALSE | AC9: FALSE | AD9: FALSE | AE9: FALSE | AF9: clean fleet
A10: =+I10 -> 46222 | B10: =+H10 -> Entered MEG | C10: 500 kb | D10: dark activity | E10: YONG TAI | F10: 9231511 | G10: GAMBIA | H10: Entered MEG | I10: 46222 | J10: Dark/Unknown Route | K10: Ballast | L10: NaN | M10: 0 | N10: bbl | O10: Zhenhai | P10: China | Q10: Jubail Industrial Port | R10: Saudi Arabia | S10: 72910 | T10: 2002 | U10: REPUBLIC OF KOREA | V10: 72.91 | W10: LR1 | X10: ballast | Y10: loading_state | Z10: 0 | AA10: FALSE | AB10: FALSE | AC10: FALSE | AD10: TRUE | AE10: FALSE | AF10: clean fleet
A11: =+I11 -> 46221 | B11: =+H11 -> Entered MEG | C11: 500 kb | D11: Clean prod | E11: KITION M | F11: 9321160 | G11: PANAMA | H11: Entered MEG | I11: 46221 | J11: Dark/Unknown Route | K11: Ballast | L11: NaN | M11: 0 | N11: bbl | O11: Merak | P11: Indonesia | Q11: Ras Laffan | R11: Qatar | S11: 74995 | T11: 2006 | U11: JAPAN | V11: 74.995 | W11: LR1 | X11: ballast | Y11: loading_state | Z11: 0 | AA11: FALSE | AB11: FALSE | AC11: FALSE | AD11: TRUE | AE11: FALSE | AF11: clean fleet
A12: =+I12 -> 46221 | B12: =+H12 -> Exited MEG | C12: 300 kb | D12: dark activity | E12: SEAWAY | F12: 9273650 | G12: PANAMA | H12: Exited MEG | I12: 46221 | J12: Iranian Route | K12: Ballast | L12: NaN | M12: 0 | N12: bbl | O12: Sohar Light. | P12: Oman | Q12: San Lorenzo | R12: Argentina | S12: 46101 | T12: 2004 | U12: REPUBLIC OF KOREA | V12: 46.101 | W12: LR1 | X12: ballast | Y12: loading_state | Z12: 0 | AA12: FALSE | AB12: FALSE | AC12: FALSE | AD12: FALSE | AE12: FALSE | AF12: clean fleet
A13: =+I13 -> 46221 | B13: =+H13 -> Entered MEG | C13: 350 kb | D13: dark activity | E13: WELL SAIL | F13: 9321938 | G13: MARSHALL ISLANDS | H13: Entered MEG | I13: 46221 | J13: Dark/Unknown Route | K13: Laden | L13: CPP | M13: 353462 | N13: bbl | O13: Iran | P13: Iran | Q13: NaN | R13: NaN | S13: 51202 | T13: 2007 | U13: REPUBLIC OF KOREA | V13: 51.202 | W13: LR1 | X13: products | Y13: tagged | Z13: 353462 | AA13: FALSE | AB13: FALSE | AC13: FALSE | AD13: TRUE | AE13: FALSE | AF13: clean fleet
A14: =+I14 -> 46220 | B14: =+H14 -> Entered MEG | C14: 500 kb | D14: Clean prod | E14: ADVANTAGE PARADISE | F14: 9577056 | G14: MARSHALL ISLANDS | H14: Entered MEG | I14: 46220 | J14: Dark/Unknown Route | K14: Ballast | L14: NaN | M14: 0 | N14: bbl | O14: Port Moresby | P14: Papua New Guinea | Q14: Jubail Industrial Port | R14: Saudi Arabia | S14: 74602 | T14: 2010 | U14: REPUBLIC OF KOREA | V14: 74.602 | W14: LR1 | X14: ballast | Y14: loading_state | Z14: 0 | AA14: FALSE | AB14: FALSE | AC14: FALSE | AD14: TRUE | AE14: FALSE | AF14: clean fleet
A15: =+I15 -> 46220 | B15: =+H15 -> Exited MEG | C15: N/A | D15: N/A | E15: AL DERWAZAH | F15: 9653410 | G15: KUWAIT | H15: Exited MEG | I15: 46220 | J15: Dark/Unknown Route | K15: Laden | L15: Crude/Co | M15: 2042484 | N15: bbl | O15: Mina Al-Ahmadi | P15: Kuwait | Q15: Sohar Light. | R15: Oman | S15: 316884 | T15: 2014 | U15: REPUBLIC OF KOREA | V15: 316.884 | W15: VLCC | X15: crude | Y15: tagged | Z15: 2042484 | AA15: FALSE | AB15: FALSE | AC15: FALSE | AD15: TRUE | AE15: FALSE | AF15: clean fleet
A16: =+I16 -> 46220 | B16: =+H16 -> Exited MEG | C16: 12 kb | D16: dark activity | E16: BLACK MAYA | F16: 9118800 | G16: CURACAO | H16: Exited MEG | I16: 46220 | J16: Iranian Route | K16: Laden | L16: DPP | M16: 11875 | N16: bbl | O16: Bandar Abbas | P16: Iran | Q16: Muscat | R16: Oman | S16: 2005 | T16: 1995 | U16: JAPAN | V16: 2.005 | W16: Below GP | X16: products | Y16: tagged | Z16: 11875 | AA16: FALSE | AB16: FALSE | AC16: FALSE | AD16: FALSE | AE16: FALSE | AF16: clean fleet
A17: =+I17 -> 46220 | B17: =+H17 -> Entered MEG | C17: 115 kb | D17: ? | E17: GOODAL | F17: 9244374 | G17: BAHAMAS | H17: Entered MEG | I17: 46220 | J17: Dark/Unknown Route | K17: Laden | L17: Veg/Bio | M17: 112978 | N17: bbl | O17: Pasir Gudang | P17: Malaysia | Q17: NaN | R17: NaN | S17: 17396 | T17: 2001 | U17: JAPAN | V17: 17.396 | W17: GP | X17: other | Y17: tagged | Z17: 0 | AA17: FALSE | AB17: FALSE | AC17: FALSE | AD17: TRUE | AE17: FALSE | AF17: clean fleet
... A19: =+I19 -> 46220 | B19: =+H19 -> Exited MEG | C19: 600 kb | D19: Crude | E19: NAVIG8 PERSEVERANCE | F19: 9853266 | G19: SINGAPORE | H19: Exited MEG | I19: 46220 | J19: Dark/Unknown Route | K19: Laden | L19: Crude/Co | M19: 603759 | N19: bbl | O19: Zirku | P19: United Arab Emirates | Q19: Sohar Light. | R19: Oman | S19: 109998 | T19: 2019 | U19: CHINA | V19: 109.998 | W19: AFRA | X19: crude | Y19: tagged | Z19: 603759 | AA19: FALSE | AB19: FALSE | AC19: FALSE | AD19: TRUE | AE19: FALSE | AF19: clean fleet
A20: =+I20 -> 46220 | B20: =+H20 -> Entered MEG | D20: VLCC | E20: NISSOS HERACLEA | F20: 9419618 | G20: LIBERIA | H20: Entered MEG | I20: 46220 | J20: Dark/Unknown Route | K20: Ballast | L20: NaN | M20: 0 | N20: bbl | O20: Sohar Light. | P20: Oman | Q20: Al Basrah | R20: Iraq | S20: 313525 | T20: 2009 | U20: REPUBLIC OF KOREA | V20: 313.525 | W20: VLCC | X20: ballast | Y20: loading_state | Z20: 0 | AA20: FALSE | AB20: FALSE | AC20: FALSE | AD20: TRUE | AE20: FALSE | AF20: clean fleet
A21: =+I21 -> 46220 | B21: =+H21 -> Entered MEG | D21: dark activity | E21: TIYARA | F21: 9231224 | G21: NICARAGUA | H21: Entered MEG | I21: 46220 | J21: Dark/Unknown Route | K21: Ballast | L21: NaN | M21: 0 | N21: bbl | O21: China | P21: China | Q21: NaN | R21: NaN | S21: 112679 | T21: 2002 | U21: REPUBLIC OF KOREA | V21: 112.679 | W21: AFRA | X21: ballast | Y21: loading_state | Z21: 0 | AA21: TRUE | AB21: TRUE | AC21: TRUE | AD21: TRUE | AE21: TRUE | AF21: dark fleet

Sheet Sheet3
D7: events | F7: volume_bbl
C8: Direction | D8: Entered MEG | E8: Exited MEG | F8: Entered MEG | G8: Exited MEG
C9: day
C10: 46190 | D10: 3 | E10: 2 | F10: 0 | G10: 589833
C11: 46191 | D11: 11 | E11: 9 | F11: 0 | G11: 9552969
C12: 46192 | D12: 4 | E12: 7 | F12: 0 | G12: 12550599
C13: 46193 | D13: 10 | E13: 14 | F13: 106776 | G13: 15230410
C14: 46194 | D14: 2 | E14: 14 | F14: 0 | G14: 16269796
C15: 46195 | D15: 11 | E15: 17 | F15: 52476 | G15: 13364577
C16: 46196 | D16: 9 | E16: 12 | F16: 0 | G16: 9694836
C17: 46197 | D17: 13 | E17: 17 | F17: 32398 | G17: 16946181
C18: 46198 | D18: 4 | E18: 24 | F18: 15391 | G18: 16798876
C19: 46199 | D19: 15 | E19: 15 | F19: 0 | G19: 10214704
C20: 46200 | D20: 13 | E20: 11 | F20: 4579 | G20: 13488749
C21: 46201 | D21: 6 | E21: 5 | F21: 0 | G21: 4793331
... C56: 46236 | D56: 1 | E56: 0 | F56: 0 | G56: 0

Sheet entries
B1: Vessel Name | C1: IMO | D1: Vessel Classification | E1: Flag Name | F1: Direction | G1: Crossing Date | H1: Crossing Type | I1: Loading State | J1: Cargo Type | K1: Quantity | L1: Quantity Unit | M1: Last Cargo Zone | N1: Last Cargo Country | O1: Next Port | P1: Next Port Country | Q1: Deadweight | R1: Build Year | S1: Build Country | T1: dwt_kdwt | U1: afra_class | V1: cargo_group | W1: cargo_source | X1: volume_bbl | Y1: sanctioned_iran | Z1: sanctioned_sdn | AA1: sanctioned_any | AB1: is_dark_route | AC1: is_dark_fleet | AD1: fleet | AE1: Manual | AF1: Kpler | AG1: Capacity
B2: JAMAICA PROSPERITY | G2: 46239 | U2: VLCC | V2: ballast | AE2: 1 | AG2: =VLOOKUP(U2,afra_scale,2,FALSE) -> 2000
B3: PANAMA PROSPERITY | C3: 9514561 | D3: VLCC | E3: LIBERIA | F3: Entered MEG | G3: 46238 | H3: Dark/Unknown Route | I3: Ballast | K3: 0 | L3: bbl | M3: Jieyang | N3: China | O3: Dubai Area | P3: United Arab Emirates | Q3: 297491 | R3: 2011 | S3: CHINA | T3: 297.491 | U3: VLCC | V3: ballast | W3: loading_state | X3: 0 | Y3: FALSE | Z3: FALSE | AA3: FALSE | AB3: TRUE | AC3: FALSE | AD3: clean fleet | AE3: 1 | AG3: =VLOOKUP(U3,afra_scale,2,FALSE) -> 2000
B4: HELGA | C4: 9176993 | D4: VLCC | E4: COMOROS | F4: Entered MEG | G4: 46236 | H4: Dark/Unknown Route | I4: Ballast | K4: 0 | L4: bbl | M4: Sohar Light. | N4: Oman | O4: Al Basrah | P4: Iraq | Q4: 298620 | R4: 2000 | S4: JAPAN | T4: 298.62 | U4: VLCC | V4: ballast | W4: loading_state | X4: 0 | Y4: FALSE | Z4: FALSE | AA4: FALSE | AB4: TRUE | AC4: FALSE | AD4: clean fleet | AE4: 1 | AG4: =VLOOKUP(U4,afra_scale,2,FALSE) -> 2000
B5: VADIN | C5: 9324100 | D5: VLCC | E5: ANTIGUA AND BARBUDA | F5: Entered MEG | G5: 46235 | H5: Dark/Unknown Route | I5: Ballast | K5: 0 | L5: bbl | M5: Sohar Light. | N5: Oman | O5: Al Rayyan | P5: Qatar | Q5: 302478 | R5: 2006 | S5: JAPAN | T5: 302.478 | U5: VLCC | V5: ballast | W5: loading_state | X5: 0 | Y5: FALSE | Z5: FALSE | AA5: FALSE | AB5: TRUE | AC5: FALSE | AD5: clean fleet | AE5: 1 | AG5: =VLOOKUP(U5,afra_scale,2,FALSE) -> 2000
B6: NISSOS HERACLEA | C6: 9419618 | D6: VLCC | E6: LIBERIA | F6: Entered MEG | G6: 46234 | H6: Dark/Unknown Route | I6: Ballast | K6: 0 | L6: bbl | M6: Sohar Light. | N6: Oman | O6: Al Basrah | P6: Iraq | Q6: 313525 | R6: 2009 | S6: REPUBLIC OF KOREA | T6: 313.525 | U6: VLCC | V6: ballast | W6: loading_state | X6: 0 | Y6: FALSE | Z6: FALSE | AA6: FALSE | AB6: TRUE | AC6: FALSE | AD6: clean fleet | AE6: 1 | AG6: =VLOOKUP(U6,afra_scale,2,FALSE) -> 2000
B7: SINBAD | C7: 9413688 | D7: Aframax/LR2 | E7: LIBERIA | F7: Entered MEG | G7: 46234 | H7: Dark/Unknown Route | I7: Ballast | K7: 0 | L7: bbl | M7: Dongjiakou | N7: China | Q7: 115928 | R7: 2009 | S7: REPUBLIC OF KOREA | T7: 115.928 | U7: AFRA | V7: ballast | W7: loading_state | X7: 0 | Y7: FALSE | Z7: FALSE | AA7: FALSE | AB7: TRUE | AC7: FALSE | AD7: clean fleet | AF7: 1 | AG7: =VLOOKUP(U7,afra_scale,2,FALSE) -> 800
B8: ON PHOENIX | C8: 9893228 | D8: Aframax/LR2 | E8: PANAMA | F8: Entered MEG | G8: 46232 | H8: Dark/Unknown Route | I8: Ballast | K8: 0 | L8: bbl | M8: Rayong | N8: Thailand | Q8: 114623 | R8: 2021 | S8: REPUBLIC OF KOREA | T8: 114.623 | U8: AFRA | V8: ballast | W8: loading_state | X8: 0 | Y8: FALSE | Z8: FALSE | AA8: FALSE | AB8: TRUE | AC8: FALSE | AD8: clean fleet | AF8: 1 | AG8: =VLOOKUP(U8,afra_scale,2,FALSE) -> 800
B9: TARIF | C9: 9828390 | D9: Aframax/LR2 | E9: LIBERIA | F9: Entered MEG | G9: 46232 | H9: Dark/Unknown Route | I9: Ballast | K9: 0 | L9: bbl | M9: Venice | N9: Italy | O9: Ruwais | P9: United Arab Emirates | Q9: 115000 | R9: 2021 | S9: CHINA | T9: 115 | U9: AFRA | V9: ballast | W9: loading_state | X9: 0 | Y9: FALSE | Z9: FALSE | AA9: FALSE | AB9: TRUE | AC9: FALSE | AD9: clean fleet | AE9: 1 | AG9: =VLOOKUP(U9,afra_scale,2,FALSE) -> 800
B10: NISSOS KEA | C10: 9920758 | D10: VLCC | E10: MARSHALL ISLANDS | F10: Entered MEG | G10: 46231 | H10: Dark/Unknown Route | I10: Ballast | K10: 0 | L10: bbl | M10: Fujairah Light. | N10: United Arab Emirates | Q10: 300323 | R10: 2022 | S10: REPUBLIC OF KOREA | T10: 300.323 | U10: VLCC | V10: ballast | W10: loading_state | X10: 0 | Y10: FALSE | Z10: FALSE | AA10: FALSE | AB10: TRUE | AC10: FALSE | AD10: clean fleet | AE10: 1 | AG10: =VLOOKUP(U10,afra_scale,2,FALSE) -> 2000
B11: ROTTERDAM ENERGY | C11: 9508859 | D11: VLCC | E11: LIBERIA | F11: Entered MEG | G11: 46230 | H11: Dark/Unknown Route | I11: Ballast | K11: 0 | L11: bbl | M11: Fujairah | N11: United Arab Emirates | O11: Das Island | P11: United Arab Emirates | Q11: 296659 | R11: 2010 | S11: CHINA | T11: 296.659 | U11: VLCC | V11: ballast | W11: loading_state | X11: 0 | Y11: FALSE | Z11: FALSE | AA11: FALSE | AB11: TRUE | AC11: FALSE | AD11: clean fleet | AE11: 1 | AG11: =VLOOKUP(U11,afra_scale,2,FALSE) -> 2000
B12: LUCIA A | C12: 9228655 | D12: Suezmax/LR3 | E12: SAN MARINO | F12: Entered MEG | G12: 46229 | H12: Dark/Unknown Route | I12: Ballast | K12: 0 | L12: bbl | M12: Ain Sukhna | N12: Egypt | O12: Al Basrah | P12: Iraq | Q12: 159997 | R12: 2003 | S12: REPUBLIC OF KOREA | T12: 159.997 | U12: LR2 | V12: ballast | W12: loading_state | X12: 0 | Y12: FALSE | Z12: FALSE | AA12: FALSE | AB12: TRUE | AC12: FALSE | AD12: clean fleet | AE12: 1 | AG12: =VLOOKUP(U12,afra_scale,2,FALSE) -> 1000
B13: ST3 | C13: 9220964 | D13: VLCC | E13: MARSHALL ISLANDS | F13: Entered MEG | G13: 46229 | H13: Dark/Unknown Route | I13: Laden | J13: DPP | K13: 46834 | L13: bbl | M13: Fujairah Light. | N13: United Arab Emirates | Q13: 302977 | R13: 2002 | S13: REPUBLIC OF KOREA | T13: 302.977 | U13: VLCC | V13: products | W13: tagged | X13: 46834 | Y13: FALSE | Z13: FALSE | AA13: FALSE | AB13: TRUE | AC13: FALSE | AD13: clean fleet | AE13: 1 | AG13: =VLOOKUP(U13,afra_scale,2,FALSE) -> 2000
B14: NISSOS KYTHNOS | C14: 9853852 | D14: VLCC | E14: MARSHALL ISLANDS | F14: Entered MEG | G14: 46228 | H14: Dark/Unknown Route | I14: Ballast | K14: 0 | L14: bbl | M14: Kiire | N14: Japan | O14: Al Shaheen | P14: Qatar | Q14: 318744 | R14: 2019 | S14: REPUBLIC OF KOREA | T14: 318.744 | U14: VLCC | V14: ballast | W14: loading_state | X14: 0 | Y14: FALSE | Z14: FALSE | AA14: FALSE | AB14: TRUE | AC14: FALSE | AD14: clean fleet | AE14: 1 | AG14: =VLOOKUP(U14,afra_scale,2,FALSE) -> 2000
B15: NOBLE | C15: 9389253 | D15: VLCC | E15: HONG KONG | F15: Entered MEG | G15: 46226 | H15: Iranian Route | I15: Ballast | K15: 0 | L15: bbl | M15: Paradip | N15: India | O15: Al Basrah | P15: Iraq | Q15: 318440 | R15: 2009 | S15: REPUBLIC OF KOREA | T15: 318.44 | U15: VLCC | V15: ballast | W15: loading_state | X15: 0 | Y15: FALSE | Z15: FALSE | AA15: FALSE | AB15: FALSE | AC15: FALSE | AD15: clean fleet | AE15: 1 | AG15: =VLOOKUP(U15,afra_scale,2,FALSE) -> 2000
B16: AL KHTAM | C16: 9823534 | D16: Aframax/LR2 | E16: LIBERIA | F16: Entered MEG | G16: 46224 | H16: Dark/Unknown Route | I16: Ballast | K16: 0 | L16: bbl | M16: Sohar Light. | N16: Oman | O16: Ruwais | P16: United Arab Emirates | Q16: 114644 | R16: 2021 | S16: CHINA | T16: 114.644 | U16: AFRA | V16: ballast | W16: loading_state | X16: 0 | Y16: FALSE | Z16: FALSE | AA16: FALSE | AB16: TRUE | AC16: FALSE | AD16: clean fleet | AF16: 1 | AG16: =VLOOKUP(U16,afra_scale,2,FALSE) -> 800
B17: AL DERWAZAH | C17: 9653410 | D17: VLCC | E17: KUWAIT | F17: Entered MEG | G17: 46223 | H17: Dark/Unknown Route | I17: Ballast | K17: 0 | L17: bbl | M17: Sohar Light. | N17: Oman | O17: Mina Al-Ahmadi | P17: Kuwait | Q17: 316884 | R17: 2014 | S17: REPUBLIC OF KOREA | T17: 316.884 | U17: VLCC | V17: ballast | W17: loading_state | X17: 0 | Y17: FALSE | Z17: FALSE | AA17: FALSE | AB17: TRUE | AC17: FALSE | AD17: clean fleet | AF17: 1 | AG17: =VLOOKUP(U17,afra_scale,2,FALSE) -> 2000
B18: ANGOLA B | C18: 9623685 | D18: VLCC | E18: LIBERIA | F18: Entered MEG | G18: 46223 | H18: Dark/Unknown Route | I18: Ballast | K18: 0 | L18: bbl | M18: Sohar Light. | N18: Oman | O18: Zirku | P18: United Arab Emirates | Q18: 299999 | R18: 2012 | S18: REPUBLIC OF KOREA | T18: 299.999 | U18: VLCC | V18: ballast | W18: loading_state | X18: 0 | Y18: FALSE | Z18: FALSE | AA18: FALSE | AB18: TRUE | AC18: FALSE | AD18: clean fleet | AE18: 1 | AG18: =VLOOKUP(U18,afra_scale,2,FALSE) -> 2000
B19: BAHRAIN PROSPERITY | C19: 9596947 | D19: VLCC | E19: LIBERIA | F19: Entered MEG | G19: 46223 | H19: Dark/Unknown Route | I19: Ballast | K19: 0 | L19: bbl | M19: Fujairah Light. | N19: United Arab Emirates | O19: Al Basrah | P19: Iraq | Q19: 299999 | R19: 2012 | S19: REPUBLIC OF KOREA | T19: 299.999 | U19: VLCC | V19: ballast | W19: loading_state | X19: 0 | Y19: FALSE | Z19: FALSE | AA19: FALSE | AB19: TRUE | AC19: FALSE | AD19: clean fleet | AE19: 1 | AG19: =VLOOKUP(U19,afra_scale,2,FALSE) -> 2000
B20: CYPRUS PROSPERITY | C20: 9595216 | D20: VLCC | E20: LIBERIA | F20: Entered MEG | G20: 46223 | H20: Dark/Unknown Route | I20: Ballast | K20: 0 | L20: bbl | M20: Fujairah Light. | N20: United Arab Emirates | O20: Ruwais | P20: United Arab Emirates | Q20: 299996 | R20: 2012 | S20: CHINA | T20: 299.996 | U20: VLCC | V20: ballast | W20: loading_state | X20: 0 | Y20: FALSE | Z20: FALSE | AA20: FALSE | AB20: TRUE | AC20: FALSE | AD20: clean fleet | AF20: 1 | AG20: =VLOOKUP(U20,afra_scale,2,FALSE) -> 2000
B21: FRANCE C | C21: 9322281 | D21: VLCC | E21: LIBERIA | F21: Entered MEG | G21: 46223 | H21: Dark/Unknown Route | I21: Ballast | K21: 0 | L21: bbl | M21: Sohar Light. | N21: Oman | O21: Zirku | P21: United Arab Emirates | Q21: 306506 | R21: 2007 | S21: REPUBLIC OF KOREA | T21: 306.506 | U21: VLCC | V21: ballast | W21: loading_state | X21: 0 | Y21: FALSE | Z21: FALSE | AA21: FALSE | AB21: TRUE | AC21: FALSE | AD21: clean fleet | AF21: 1 | AG21: =VLOOKUP(U21,afra_scale,2,FALSE) -> 2000
B22: NAVIG8 PERSEVERANCE | C22: 9853266 | D22: Aframax/LR2 | E22: SINGAPORE | F22: Entered MEG | G22: 46223 | H22: Dark/Unknown Route | I22: Ballast | K22: 0 | L22: bbl | M22: Sohar Light. | N22: Oman | Q22: 109998 | R22: 2019 | S22: CHINA | T22: 109.998 | U22: AFRA | V22: ballast | W22: loading_state | X22: 0 | Y22: FALSE | Z22: FALSE | AA22: FALSE | AB22: TRUE | AC22: FALSE | AD22: clean fleet | AE22: 1 | AG22: =VLOOKUP(U22,afra_scale,2,FALSE) -> 800
B23: KOS | C23: 1024950 | D23: Aframax/LR2 | E23: LIBERIA | F23: Entered MEG | G23: 46222 | H23: Dark/Unknown Route | I23: Ballast | K23: 0 | L23: bbl | M23: Singapore | N23: Singapore Republic | O23: Ras Tanura | P23: Saudi Arabia | Q23: 115026 | R23: 2025 | S23: CHINA | T23: 115.026 | U23: AFRA | V23: ballast | W23: loading_state | X23: 0 | Y23: FALSE | Z23: FALSE | AA23: FALSE | AB23: TRUE | AC23: FALSE | AD23: clean fleet | AF23: 1 | AG23: =VLOOKUP(U23,afra_scale,2,FALSE) -> 800
B24: AL YARMOUK | C24: 9653422 | D24: VLCC | E24: KUWAIT | F24: Entered MEG | G24: 46221 | H24: Dark/Unknown Route | I24: Ballast | K24: 0 | L24: bbl | M24: Gulf of Oman | O24: Mina Al-Ahmadi | P24: Kuwait | Q24: 317033 | R24: 2014 | S24: REPUBLIC OF KOREA | T24: 317.033 | U24: VLCC | V24: ballast | W24: loading_state | X24: 0 | Y24: FALSE | Z24: FALSE | AA24: FALSE | AB24: TRUE | AC24: FALSE | AD24: clean fleet | AF24: 1 | AG24: =VLOOKUP(U24,afra_scale,2,FALSE) -> 2000
B25: NISSOS HERACLEA | C25: 9419618 | D25: VLCC | E25: LIBERIA | F25: Entered MEG | G25: 46220 | H25: Dark/Unknown Route | I25: Ballast | K25: 0 | L25: bbl | M25: Sohar Light. | N25: Oman | O25: Al Basrah | P25: Iraq | Q25: 313525 | R25: 2009 | S25: REPUBLIC OF KOREA | T25: 313.525 | U25: VLCC | V25: ballast | W25: loading_state | X25: 0 | Y25: FALSE | Z25: FALSE | AA25: FALSE | AB25: TRUE | AC25: FALSE | AD25: clean fleet | AE25: 1 | AG25: =VLOOKUP(U25,afra_scale,2,FALSE) -> 2000
B26: PHILIPPINES PROSPERITY | C26: 9377420 | D26: VLCC | E26: LIBERIA | F26: Entered MEG | G26: 46219 | H26: Dark/Unknown Route | I26: Ballast | K26: 0 | L26: bbl | M26: Kikuma | N26: Japan | O26: Al Shaheen | P26: Qatar | Q26: 302550 | R26: 2011 | S26: JAPAN | T26: 302.55 | U26: VLCC | V26: ballast | W26: loading_state | X26: 0 | Y26: FALSE | Z26: FALSE | AA26: FALSE | AB26: TRUE | AC26: FALSE | AD26: clean fleet | AF26: 1 | AG26: =VLOOKUP(U26,afra_scale,2,FALSE) -> 2000
B27: GRAND LADY | C27: 9406166 | D27: VLCC | E27: CYPRUS | F27: Entered MEG | G27: 46218 | H27: Dark/Unknown Route | I27: Ballast | K27: 0 | L27: bbl | M27: Fujairah Light. | N27: United Arab Emirates | Q27: 299999 | R27: 2011 | S27: JAPAN | T27: 299.999 | U27: VLCC | V27: ballast | W27: loading_state | X27: 0 | Y27: FALSE | Z27: FALSE | AA27: FALSE | AB27: TRUE | AC27: FALSE | AD27: clean fleet | AE27: 1 | AG27: =VLOOKUP(U27,afra_scale,2,FALSE) -> 2000
B28: BAHRA | C28: 9595008 | D28: Aframax/LR2 | E28: KUWAIT | F28: Entered MEG | G28: 46217 | H28: Dark/Unknown Route | I28: Ballast | K28: 0 | L28: bbl | M28: Kutch Light. | N28: India | Q28: 110761 | R28: 2012 | S28: REPUBLIC OF KOREA | T28: 110.761 | U28: AFRA | V28: ballast | W28: loading_state | X28: 0 | Y28: FALSE | Z28: FALSE | AA28: FALSE | AB28: TRUE | AC28: FALSE | AD28: clean fleet | AF28: 1 | AG28: =VLOOKUP(U28,afra_scale,2,FALSE) -> 800
B29: NAVIG8 PERSEVERANCE | C29: 9853266 | D29: Aframax/LR2 | E29: SINGAPORE | F29: Entered MEG | G29: 46217 | H29: Dark/Unknown Route | I29: Ballast | K29: 0 | L29: bbl | M29: Nipah Light. | N29: Indonesia | O29: Zirku | P29: United Arab Emirates | Q29: 109998 | R29: 2019 | S29: CHINA | T29: 109.998 | U29: AFRA | V29: ballast | W29: loading_state | X29: 0 | Y29: FALSE | Z29: FALSE | AA29: FALSE | AB29: TRUE | AC29: FALSE | AD29: clean fleet | AE29: 1 | AG29: =VLOOKUP(U29,afra_scale,2,FALSE) -> 800
B30: ACHELOOS | C30: 1087524 | D30: VLCC | E30: LIBERIA | F30: Entered MEG | G30: 46216 | H30: Dark/Unknown Route | I30: Ballast | K30: 0 | L30: bbl | M30: Changxing | N30: China | O30: Al Basrah | P30: Iraq | Q30: 306000 | R30: 2026 | S30: CHINA | T30: 306 | U30: VLCC | V30: ballast | W30: loading_state | X30: 0 | Y30: FALSE | Z30: FALSE | AA30: FALSE | AB30: TRUE | AC30: FALSE | AD30: clean fleet | AF30: 1 | AG30: =VLOOKUP(U30,afra_scale,2,FALSE) -> 2000
B31: AL SALMI | C31: 9534793 | D31: VLCC | E31: KUWAIT | F31: Entered MEG | G31: 46216 | H31: Dark/Unknown Route | I31: Ballast | K31: 0 | L31: bbl | M31: Gulf of Oman | O31: Mina Al-Ahmadi | P31: Kuwait | Q31: 319660 | R31: 2011 | S31: REPUBLIC OF KOREA | T31: 319.66 | U31: VLCC | V31: ballast | W31: loading_state | X31: 0 | Y31: FALSE | Z31: FALSE | AA31: FALSE | AB31: TRUE | AC31: FALSE | AD31: clean fleet | AF31: 1 | AG31: =VLOOKUP(U31,afra_scale,2,FALSE) -> 2000
B32: DAR SALWA | C32: 9534779 | D32: VLCC | E32: KUWAIT | F32: Entered MEG | G32: 46216 | H32: Dark/Unknown Route | I32: Ballast | K32: 0 | L32: bbl | M32: Sohar Light. | N32: Oman | O32: Mina Al-Ahmadi | P32: Kuwait | Q32: 319761 | R32: 2010 | S32: REPUBLIC OF KOREA | T32: 319.761 | U32: VLCC | V32: ballast | W32: loading_state | X32: 0 | Y32: FALSE | Z32: FALSE | AA32: FALSE | AB32: TRUE | AC32: FALSE | AD32: clean fleet | AE32: 1 | AG32: =VLOOKUP(U32,afra_scale,2,FALSE) -> 2000
B33: NEW GIANT | C33: 9516947 | D33: VLCC | E33: LIBERIA | F33: Entered MEG | G33: 46216 | H33: Dark/Unknown Route | I33: Ballast | K33: 0 | L33: bbl | M33: Tanjung Bruas Light. | N33: Malaysia | O33: Al Basrah | P33: Iraq | Q33: 319611 | R33: 2016 | S33: CHINA | T33: 319.611 | U33: VLCC | V33: ballast | W33: loading_state | X33: 0 | Y33: FALSE | Z33: FALSE | AA33: FALSE | AB33: TRUE | AC33: FALSE | AD33: clean fleet | AE33: 1 | AG33: =VLOOKUP(U33,afra_scale,2,FALSE) -> 2000
B34: ARGENTINA B | C34: 9389021 | D34: VLCC | E34: LIBERIA | F34: Entered MEG | G34: 46215 | H34: Dark/Unknown Route | I34: Ballast | K34: 0 | L34: bbl | M34: Gulf of Oman | O34: Al Basrah | P34: Iraq | Q34: 299999 | R34: 2009 | S34: REPUBLIC OF KOREA | T34: 299.999 | U34: VLCC | V34: ballast | W34: loading_state | X34: 0 | Y34: FALSE | Z34: FALSE | AA34: FALSE | AB34: TRUE | AC34: FALSE | AD34: clean fleet | AE34: 1 | AG34: =VLOOKUP(U34,afra_scale,2,FALSE) -> 2000
B35: DAS | C35: 9854507 | D35: VLCC | E35: LIBERIA | F35: Entered MEG | G35: 46215 | H35: Dark/Unknown Route | I35: Ballast | K35: 0 | L35: bbl | M35: Fujairah Light. | N35: United Arab Emirates | O35: Zirku | P35: United Arab Emirates | Q35: 299995 | R35: 2019 | S35: REPUBLIC OF KOREA | T35: 299.995 | U35: VLCC | V35: ballast | W35: loading_state | X35: 0 | Y35: FALSE | Z35: FALSE | AA35: FALSE | AB35: TRUE | AC35: FALSE | AD35: clean fleet | AE35: 1 | AG35: =VLOOKUP(U35,afra_scale,2,FALSE) -> 2000
B36: KIKU | C36: 9329796 | D36: VLCC | E36: PANAMA | F36: Entered MEG | G36: 46215 | H36: Dark/Unknown Route | I36: Ballast | K36: 0 | L36: bbl | M36: Fujairah Light. | N36: United Arab Emirates | O36: Mesaieed | P36: Qatar | Q36: 300866 | R36: 2006 | S36: JAPAN | T36: 300.866 | U36: VLCC | V36: ballast | W36: loading_state | X36: 0 | Y36: FALSE | Z36: FALSE | AA36: FALSE | AB36: TRUE | AC36: FALSE | AD36: clean fleet | AE36: 1 | AG36: =VLOOKUP(U36,afra_scale,2,FALSE) -> 2000

Sheet mapping
C2: class | D2: capacity
C3: VLCC | D3: 2000
C4: AFRA | D4: 800
C5: LR2 | D5: 1000
