Workbook

Sheet das_tank_inventories_daily
A1: destruction_date | B1: location | C1: value_date | D1: latitude | E1: stock | F1: acquisition_date | G1: longitude | H1: tank_id | I1: creation_date | J1: shape | K1: capacity | L1: tank_type | M1: stock_change | N1: utilization
B2: dasIslandTerminal_adnoc | C2: 46247 | D2: 25.154981 | E2: 150394.11 | F2: 46246.606 | G2: 52.876187 | H2: dasIsland_9 | J2: ADNOC - Das Island terminal | K2: 577007.91 | L2: C | M2: 0 | N2: 0.26064481
B3: dasIslandTerminal_adnoc | C3: 46246 | D3: 25.154981 | E3: 530384.25 | F3: 46243.099 | G3: 52.876187 | H3: dasIsland_9 | J3: ADNOC - Das Island terminal | K3: 577007.91 | L3: C | M3: 379990.13 | N3: 0.91919754
B4: dasIslandTerminal_adnoc | C4: 46245 | D4: 25.154981 | E4: 530384.25 | F4: 46243.099 | G4: 52.876187 | H4: dasIsland_9 | J4: ADNOC - Das Island terminal | K4: 577007.91 | L4: C | M4: 0 | N4: 0.91919754
B5: dasIslandTerminal_adnoc | C5: 46244 | D5: 25.154981 | E5: 530384.25 | F5: 46243.099 | G5: 52.876187 | H5: dasIsland_9 | J5: ADNOC - Das Island terminal | K5: 577007.91 | L5: C | M5: 0 | N5: 0.91919754
B6: dasIslandTerminal_adnoc | C6: 46243 | D6: 25.154981 | E6: 139675.5 | F6: 46240.606 | G6: 52.876187 | H6: dasIsland_9 | J6: ADNOC - Das Island terminal | K6: 577007.91 | L6: C | M6: -390708.75 | N6: 0.2420686
B7: dasIslandTerminal_adnoc | C7: 46242 | D7: 25.154981 | E7: 139675.5 | F7: 46240.606 | G7: 52.876187 | H7: dasIsland_9 | J7: ADNOC - Das Island terminal | K7: 577007.91 | L7: C | M7: 0 | N7: 0.2420686
B8: dasIslandTerminal_adnoc | C8: 46241 | D8: 25.154981 | E8: 139675.5 | F8: 46240.606 | G8: 52.876187 | H8: dasIsland_9 | J8: ADNOC - Das Island terminal | K8: 577007.91 | L8: C | M8: 0 | N8: 0.2420686
B9: dasIslandTerminal_adnoc | C9: 46240 | D9: 25.154981 | E9: 208982.62 | F9: 46237.099 | G9: 52.876187 | H9: dasIsland_9 | J9: ADNOC - Das Island terminal | K9: 577007.91 | L9: C | M9: 69307.123 | N9: 0.36218328
B10: dasIslandTerminal_adnoc | C10: 46239 | D10: 25.154981 | E10: 208982.62 | F10: 46237.099 | G10: 52.876187 | H10: dasIsland_9 | J10: ADNOC - Das Island terminal | K10: 577007.91 | L10: C | M10: 0 | N10: 0.36218328
B11: dasIslandTerminal_adnoc | C11: 46238 | D11: 25.154981 | E11: 208982.62 | F11: 46237.099 | G11: 52.876187 | H11: dasIsland_9 | J11: ADNOC - Das Island terminal | K11: 577007.91 | L11: C | M11: 0 | N11: 0.36218328
B12: dasIslandTerminal_adnoc | C12: 46237 | D12: 25.154981 | E12: 297663.58 | F12: 46234.606 | G12: 52.876187 | H12: dasIsland_9 | J12: ADNOC - Das Island terminal | K12: 577007.91 | L12: C | M12: 88680.961 | N12: 0.51587435
B13: dasIslandTerminal_adnoc | C13: 46236 | D13: 25.154981 | E13: 297663.58 | F13: 46234.606 | G13: 52.876187 | H13: dasIsland_9 | J13: ADNOC - Das Island terminal | K13: 577007.91 | L13: C | M13: 0 | N13: 0.51587435
... B897: dasIslandTerminal_adnoc | C897: 46024 | D897: 25.15578 | E897: 126349.28 | F897: 46023.606 | G897: 52.87382 | H897: dasIsland_6 | J897: ADNOC - Das Island terminal | K897: 689407.19 | L897: C | M897: 0 | N897: 0.18327236
A898: 43864 | B898: dasIslandTerminal_adnoc | C898: 46247 | D898: 25.155889 | E898: 0 | F898: 43863.606 | G898: 52.872942 | H898: dasIsland_5 | J898: ADNOC - Das Island terminal | K898: 0 | L898: C | M898: 0 | N898: 0
A899: 43864 | B899: dasIslandTerminal_adnoc | C899: 46246 | D899: 25.155889 | E899: 0 | F899: 43863.606 | G899: 52.872942 | H899: dasIsland_5 | J899: ADNOC - Das Island terminal | K899: 0 | L899: C | M899: 0 | N899: 0
A900: 43864 | B900: dasIslandTerminal_adnoc | C900: 46245 | D900: 25.155889 | E900: 0 | F900: 43863.606 | G900: 52.872942 | H900: dasIsland_5 | J900: ADNOC - Das Island terminal | K900: 0 | L900: C | M900: 0 | N900: 0
A901: 43864 | B901: dasIslandTerminal_adnoc | C901: 46244 | D901: 25.155889 | E901: 0 | F901: 43863.606 | G901: 52.872942 | H901: dasIsland_5 | J901: ADNOC - Das Island terminal | K901: 0 | L901: C | M901: 0 | N901: 0
A902: 43864 | B902: dasIslandTerminal_adnoc | C902: 46243 | D902: 25.155889 | E902: 0 | F902: 43863.606 | G902: 52.872942 | H902: dasIsland_5 | J902: ADNOC - Das Island terminal | K902: 0 | L902: C | M902: 0 | N902: 0
A903: 43864 | B903: dasIslandTerminal_adnoc | C903: 46242 | D903: 25.155889 | E903: 0 | F903: 43863.606 | G903: 52.872942 | H903: dasIsland_5 | J903: ADNOC - Das Island terminal | K903: 0 | L903: C | M903: 0 | N903: 0
A904: 43864 | B904: dasIslandTerminal_adnoc | C904: 46241 | D904: 25.155889 | E904: 0 | F904: 43863.606 | G904: 52.872942 | H904: dasIsland_5 | J904: ADNOC - Das Island terminal | K904: 0 | L904: C | M904: 0 | N904: 0
A905: 43864 | B905: dasIslandTerminal_adnoc | C905: 46240 | D905: 25.155889 | E905: 0 | F905: 43863.606 | G905: 52.872942 | H905: dasIsland_5 | J905: ADNOC - Das Island terminal | K905: 0 | L905: C | M905: 0 | N905: 0
A906: 43864 | B906: dasIslandTerminal_adnoc | C906: 46239 | D906: 25.155889 | E906: 0 | F906: 43863.606 | G906: 52.872942 | H906: dasIsland_5 | J906: ADNOC - Das Island terminal | K906: 0 | L906: C | M906: 0 | N906: 0
A907: 43864 | B907: dasIslandTerminal_adnoc | C907: 46238 | D907: 25.155889 | E907: 0 | F907: 43863.606 | G907: 52.872942 | H907: dasIsland_5 | J907: ADNOC - Das Island terminal | K907: 0 | L907: C | M907: 0 | N907: 0
A908: 43864 | B908: dasIslandTerminal_adnoc | C908: 46237 | D908: 25.155889 | E908: 0 | F908: 43863.606 | G908: 52.872942 | H908: dasIsland_5 | J908: ADNOC - Das Island terminal | K908: 0 | L908: C | M908: 0 | N908: 0
A909: 43864 | B909: dasIslandTerminal_adnoc | C909: 46236 | D909: 25.155889 | E909: 0 | F909: 43863.606 | G909: 52.872942 | H909: dasIsland_5 | J909: ADNOC - Das Island terminal | K909: 0 | L909: C | M909: 0 | N909: 0
... A1121: 43864 | B1121: dasIslandTerminal_adnoc | C1121: 46024 | D1121: 25.155889 | E1121: 0 | F1121: 43863.606 | G1121: 52.872942 | H1121: dasIsland_5 | J1121: ADNOC - Das Island terminal | K1121: 0 | L1121: C | M1121: 0 | N1121: 0
B1122: dasIslandTerminal_adnoc | C1122: 46247 | D1122: 25.157508 | E1122: 577007.91 | F1122: 46246.606 | G1122: 52.876708 | H1122: dasIsland_4 | J1122: ADNOC - Das Island terminal | K1122: 577007.91 | L1122: C | M1122: 0 | N1122: 1
B1123: dasIslandTerminal_adnoc | C1123: 46246 | D1123: 25.157508 | E1123: 112260.17 | F1123: 46243.099 | G1123: 52.876708 | H1123: dasIsland_4 | J1123: ADNOC - Das Island terminal | K1123: 577007.91 | L1123: C | M1123: -464747.73 | N1123: 0.19455569
B1124: dasIslandTerminal_adnoc | C1124: 46245 | D1124: 25.157508 | E1124: 112260.17 | F1124: 46243.099 | G1124: 52.876708 | H1124: dasIsland_4 | J1124: ADNOC - Das Island terminal | K1124: 577007.91 | L1124: C | M1124: 0 | N1124: 0.19455569
B1125: dasIslandTerminal_adnoc | C1125: 46244 | D1125: 25.157508 | E1125: 112260.17 | F1125: 46243.099 | G1125: 52.876708 | H1125: dasIsland_4 | J1125: ADNOC - Das Island terminal | K1125: 577007.91 | L1125: C | M1125: 0 | N1125: 0.19455569
B1126: dasIslandTerminal_adnoc | C1126: 46243 | D1126: 25.157508 | E1126: 577007.91 | F1126: 46240.606 | G1126: 52.876708 | H1126: dasIsland_4 | J1126: ADNOC - Das Island terminal | K1126: 577007.91 | L1126: C | M1126: 464747.73 | N1126: 1
B1127: dasIslandTerminal_adnoc | C1127: 46242 | D1127: 25.157508 | E1127: 577007.91 | F1127: 46240.606 | G1127: 52.876708 | H1127: dasIsland_4 | J1127: ADNOC - Das Island terminal | K1127: 577007.91 | L1127: C | M1127: 0 | N1127: 1
B1128: dasIslandTerminal_adnoc | C1128: 46241 | D1128: 25.157508 | E1128: 577007.91 | F1128: 46240.606 | G1128: 52.876708 | H1128: dasIsland_4 | J1128: ADNOC - Das Island terminal | K1128: 577007.91 | L1128: C | M1128: 0 | N1128: 1
B1129: dasIslandTerminal_adnoc | C1129: 46240 | D1129: 25.157508 | E1129: 111144.15 | F1129: 46237.099 | G1129: 52.876708 | H1129: dasIsland_4 | J1129: ADNOC - Das Island terminal | K1129: 577007.91 | L1129: C | M1129: -465863.75 | N1129: 0.19262154
B1130: dasIslandTerminal_adnoc | C1130: 46239 | D1130: 25.157508 | E1130: 111144.15 | F1130: 46237.099 | G1130: 52.876708 | H1130: dasIsland_4 | J1130: ADNOC - Das Island terminal | K1130: 577007.91 | L1130: C | M1130: 0 | N1130: 0.19262154
B1131: dasIslandTerminal_adnoc | C1131: 46238 | D1131: 25.157508 | E1131: 111144.15 | F1131: 46237.099 | G1131: 52.876708 | H1131: dasIsland_4 | J1131: ADNOC - Das Island terminal | K1131: 577007.91 | L1131: C | M1131: 0 | N1131: 0.19262154
B1132: dasIslandTerminal_adnoc | C1132: 46237 | D1132: 25.157508 | E1132: 121910.7 | F1132: 46234.606 | G1132: 52.876708 | H1132: dasIsland_4 | J1132: ADNOC - Das Island terminal | K1132: 577007.91 | L1132: C | M1132: 10766.549 | N1132: 0.21128082
B1133: dasIslandTerminal_adnoc | C1133: 46236 | D1133: 25.157508 | E1133: 121910.7 | F1133: 46234.606 | G1133: 52.876708 | H1133: dasIsland_4 | J1133: ADNOC - Das Island terminal | K1133: 577007.91 | L1133: C | M1133: 0 | N1133: 0.21128082
... B2017: dasIslandTerminal_adnoc | C2017: 46024 | D2017: 25.158622 | E2017: 8414.1526 | F2017: 46023.606 | G2017: 52.875832 | H2017: dasIsland_1 | J2017: ADNOC - Das Island terminal | K2017: 168621.72 | L2017: C | M2017: 0 | N2017: 0.049899577
...

Sheet calculations
B1: date | C1: dasIsland_0 | D1: dasIsland_1 | E1: dasIsland_10 | F1: dasIsland_11 | G1: dasIsland_12 | H1: dasIsland_13 | I1: dasIsland_14 | J1: dasIsland_15 | K1: dasIsland_16 | L1: dasIsland_17 | M1: dasIsland_18 | N1: dasIsland_2 | O1: dasIsland_3 | P1: dasIsland_4 | Q1: dasIsland_5 | R1: dasIsland_6 | S1: dasIsland_7 | T1: dasIsland_8 | U1: dasIsland_9 | W1: Date | X1: tank_draw | Y1: tank_builds | AB1: Date | AC1: tank_draw | AD1: tank_builds
B4: 46026 | C4: =+SUMIFS(das_tank_inventories_daily!$M:$M,das_tank_inventories_daily!$C:$C,calculations!$B4,das_tank_inventories_daily!$H:$H,calculations!C$1) -> -3672.1549 | D4: =+SUMIFS(das_tank_inventories_daily!$M:$M,das_tank_inventories_daily!$C:$C,calculations!$B4,das_tank_inventories_daily!$H:$H,calculations!D$1) -> -4381.1958 | E4: =+SUMIFS(das_tank_inventories_daily!$M:$M,das_tank_inventories_daily!$C:$C,calculations!$B4,das_tank_inventories_daily!$H:$H,calculations!E$1) -> -349259.65 | F4: =+SUMIFS(das_tank_inventories_daily!$M:$M,das_tank_inventories_daily!$C:$C,calculations!$B4,das_tank_inventories_daily!$H:$H,calculations!F$1) -> 0 | G4: =+SUMIFS(das_tank_inventories_daily!$M:$M,das_tank_inventories_daily!$C:$C,calculations!$B4,das_tank_inventories_daily!$H:$H,calculations!G$1) -> -9540.8496 | H4: =+SUMIFS(das_tank_inventories_daily!$M:$M,das_tank_inventories_daily!$C:$C,calculations!$B4,das_tank_inventories_daily!$H:$H,calculations!H$1) -> -20155.896 | I4: =+SUMIFS(das_tank_inventories_daily!$M:$M,das_tank_inventories_daily!$C:$C,calculations!$B4,das_tank_inventories_daily!$H:$H,calculations!I$1) -> -6022.3836 | J4: =+SUMIFS(das_tank_inventories_daily!$M:$M,das_tank_inventories_daily!$C:$C,calculations!$B4,das_tank_inventories_daily!$H:$H,calculations!J$1) -> -1495.1518 | ... U4: =+SUMIFS(das_tank_inventories_daily!$M:$M,das_tank_inventories_daily!$C:$C,calculations!$B4,das_tank_inventories_daily!$H:$H,calculations!U$1) -> -230586.45 | W4: =+B4 -> 46026 | X4: =+SUMIFS(C4:U4,C4:U4,"<0") -> -1209323.7 | Y4: =+SUMIFS(C4:U4,C4:U4,"<0") -> -1209323.7 | Z4: =+Y4+X4 -> -2418647.4 | AB4: =+B4 -> 46026 | AC4: =+SUMIFS(C4:U4,C4:U4,"<0")/3 -> -403107.91 | AD4: =+SUMIFS(C4:U4,C4:U4,">0")/3 -> 733030.47 | AE4: =+AD4+AC4 -> 329922.56
B7: 46029 | C7: =+SUMIFS(das_tank_inventories_daily!$M:$M,das_tank_inventories_daily!$C:$C,calculations!$B7,das_tank_inventories_daily!$H:$H,calculations!C$1) -> 6517.4969 | D7: =+SUMIFS(das_tank_inventories_daily!$M:$M,das_tank_inventories_daily!$C:$C,calculations!$B7,das_tank_inventories_daily!$H:$H,calculations!D$1) -> 5693.0468 | E7: =+SUMIFS(das_tank_inventories_daily!$M:$M,das_tank_inventories_daily!$C:$C,calculations!$B7,das_tank_inventories_daily!$H:$H,calculations!E$1) -> 234296.1 | F7: =+SUMIFS(das_tank_inventories_daily!$M:$M,das_tank_inventories_daily!$C:$C,calculations!$B7,das_tank_inventories_daily!$H:$H,calculations!F$1) -> 479067.73 | G7: =+SUMIFS(das_tank_inventories_daily!$M:$M,das_tank_inventories_daily!$C:$C,calculations!$B7,das_tank_inventories_daily!$H:$H,calculations!G$1) -> 19824.708 | H7: =+SUMIFS(das_tank_inventories_daily!$M:$M,das_tank_inventories_daily!$C:$C,calculations!$B7,das_tank_inventories_daily!$H:$H,calculations!H$1) -> -261686.82 | I7: =+SUMIFS(das_tank_inventories_daily!$M:$M,das_tank_inventories_daily!$C:$C,calculations!$B7,das_tank_inventories_daily!$H:$H,calculations!I$1) -> -473078.76 | J7: =+SUMIFS(das_tank_inventories_daily!$M:$M,das_tank_inventories_daily!$C:$C,calculations!$B7,das_tank_inventories_daily!$H:$H,calculations!J$1) -> -174639.19 | ... U7: =+SUMIFS(das_tank_inventories_daily!$M:$M,das_tank_inventories_daily!$C:$C,calculations!$B7,das_tank_inventories_daily!$H:$H,calculations!U$1) -> 189866.97 | W7: =+B7 -> 46029 | X7: =+SUMIFS(C7:U7,C7:U7,"<0") -> -2238216.8 | Y7: =+SUMIFS(C7:U7,C7:U7,"<0") -> -2238216.8 | Z7: =+Y7+X7 -> -4476433.6 | AB7: =+B7 -> 46029 | AC7: =+SUMIFS(C7:U7,C7:U7,"<0")/(AB7-AB4) -> -746072.26 | AD7: =+SUMIFS(C7:U7,C7:U7,">0")/(AB7-AB4) -> 450186.22 | AE7: =+AD7+AC7 -> -295886.04
AC8: =+SUMIFS(C8:U8,C8:U8,"<0")/(AB8-AB5) -> #DIV/0! | AD8: =+SUMIFS(C8:U8,C8:U8,">0")/(AB8-AB5) -> #DIV/0!
AC9: =+SUMIFS(C9:U9,C9:U9,"<0")/(AB9-AB6) -> #DIV/0! | AD9: =+SUMIFS(C9:U9,C9:U9,">0")/(AB9-AB6) -> #DIV/0!
B10: 46032 | C10: =+SUMIFS(das_tank_inventories_daily!$M:$M,das_tank_inventories_daily!$C:$C,calculations!$B10,das_tank_inventories_daily!$H:$H,calculations!C$1) -> -5982.206 | D10: =+SUMIFS(das_tank_inventories_daily!$M:$M,das_tank_inventories_daily!$C:$C,calculations!$B10,das_tank_inventories_daily!$H:$H,calculations!D$1) -> -9299.6618 | E10: =+SUMIFS(das_tank_inventories_daily!$M:$M,das_tank_inventories_daily!$C:$C,calculations!$B10,das_tank_inventories_daily!$H:$H,calculations!E$1) -> -270393.29 | F10: =+SUMIFS(das_tank_inventories_daily!$M:$M,das_tank_inventories_daily!$C:$C,calculations!$B10,das_tank_inventories_daily!$H:$H,calculations!F$1) -> -45747.704 | G10: =+SUMIFS(das_tank_inventories_daily!$M:$M,das_tank_inventories_daily!$C:$C,calculations!$B10,das_tank_inventories_daily!$H:$H,calculations!G$1) -> -20019.328 | H10: =+SUMIFS(das_tank_inventories_daily!$M:$M,das_tank_inventories_daily!$C:$C,calculations!$B10,das_tank_inventories_daily!$H:$H,calculations!H$1) -> -162352.01 | I10: =+SUMIFS(das_tank_inventories_daily!$M:$M,das_tank_inventories_daily!$C:$C,calculations!$B10,das_tank_inventories_daily!$H:$H,calculations!I$1) -> 28714.785 | J10: =+SUMIFS(das_tank_inventories_daily!$M:$M,das_tank_inventories_daily!$C:$C,calculations!$B10,das_tank_inventories_daily!$H:$H,calculations!J$1) -> -32661.09 | ... U10: =+SUMIFS(das_tank_inventories_daily!$M:$M,das_tank_inventories_daily!$C:$C,calculations!$B10,das_tank_inventories_daily!$H:$H,calculations!U$1) -> 123685.5 | W10: =+B10 -> 46032 | X10: =+SUMIFS(C10:U10,C10:U10,"<0") -> -630031.27 | Y10: =+SUMIFS(C10:U10,C10:U10,"<0") -> -630031.27 | Z10: =+Y10+X10 -> -1260062.5 | AB10: =+B10 -> 46032 | AC10: =+SUMIFS(C10:U10,C10:U10,"<0")/(AB10-AB7) -> -210010.42 | AD10: =+SUMIFS(C10:U10,C10:U10,">0")/(AB10-AB7) -> 533452.02 | AE10: =+AD10+AC10 -> 323441.59
AC11: =+SUMIFS(C11:U11,C11:U11,"<0")/(AB11-AB8) -> #DIV/0! | AD11: =+SUMIFS(C11:U11,C11:U11,">0")/(AB11-AB8) -> #DIV/0!
AC12: =+SUMIFS(C12:U12,C12:U12,"<0")/(AB12-AB9) -> #DIV/0! | AD12: =+SUMIFS(C12:U12,C12:U12,">0")/(AB12-AB9) -> #DIV/0!
B13: 46035 | C13: =+SUMIFS(das_tank_inventories_daily!$M:$M,das_tank_inventories_daily!$C:$C,calculations!$B13,das_tank_inventories_daily!$H:$H,calculations!C$1) -> 4015.4135 | D13: =+SUMIFS(das_tank_inventories_daily!$M:$M,das_tank_inventories_daily!$C:$C,calculations!$B13,das_tank_inventories_daily!$H:$H,calculations!D$1) -> 7872.5194 | E13: =+SUMIFS(das_tank_inventories_daily!$M:$M,das_tank_inventories_daily!$C:$C,calculations!$B13,das_tank_inventories_daily!$H:$H,calculations!E$1) -> 382014.11 | F13: =+SUMIFS(das_tank_inventories_daily!$M:$M,das_tank_inventories_daily!$C:$C,calculations!$B13,das_tank_inventories_daily!$H:$H,calculations!F$1) -> -110446.73 | G13: =+SUMIFS(das_tank_inventories_daily!$M:$M,das_tank_inventories_daily!$C:$C,calculations!$B13,das_tank_inventories_daily!$H:$H,calculations!G$1) -> 13275.868 | H13: =+SUMIFS(das_tank_inventories_daily!$M:$M,das_tank_inventories_daily!$C:$C,calculations!$B13,das_tank_inventories_daily!$H:$H,calculations!H$1) -> 31361.084 | I13: =+SUMIFS(das_tank_inventories_daily!$M:$M,das_tank_inventories_daily!$C:$C,calculations!$B13,das_tank_inventories_daily!$H:$H,calculations!I$1) -> 113278.18 | J13: =+SUMIFS(das_tank_inventories_daily!$M:$M,das_tank_inventories_daily!$C:$C,calculations!$B13,das_tank_inventories_daily!$H:$H,calculations!J$1) -> 36085.692 | ... U13: =+SUMIFS(das_tank_inventories_daily!$M:$M,das_tank_inventories_daily!$C:$C,calculations!$B13,das_tank_inventories_daily!$H:$H,calculations!U$1) -> -384976.74 | W13: =+B13 -> 46035 | X13: =+SUMIFS(C13:U13,C13:U13,"<0") -> -1523795.3 | Y13: =+SUMIFS(C13:U13,C13:U13,"<0") -> -1523795.3 | Z13: =+Y13+X13 -> -3047590.5 | AB13: =+B13 -> 46035 | AC13: =+SUMIFS(C13:U13,C13:U13,"<0")/(AB13-AB10) -> -507931.76 | AD13: =+SUMIFS(C13:U13,C13:U13,">0")/(AB13-AB10) -> 323503.99 | AE13: =+AD13+AC13 -> -184427.77
AC14: =+SUMIFS(C14:U14,C14:U14,"<0")/(AB14-AB11) -> #DIV/0! | AD14: =+SUMIFS(C14:U14,C14:U14,">0")/(AB14-AB11) -> #DIV/0!
AC15: =+SUMIFS(C15:U15,C15:U15,"<0")/(AB15-AB12) -> #DIV/0! | AD15: =+SUMIFS(C15:U15,C15:U15,">0")/(AB15-AB12) -> #DIV/0!
B16: 46038 | C16: =+SUMIFS(das_tank_inventories_daily!$M:$M,das_tank_inventories_daily!$C:$C,calculations!$B16,das_tank_inventories_daily!$H:$H,calculations!C$1) -> -4443.8823 | D16: =+SUMIFS(das_tank_inventories_daily!$M:$M,das_tank_inventories_daily!$C:$C,calculations!$B16,das_tank_inventories_daily!$H:$H,calculations!D$1) -> -5323.9079 | E16: =+SUMIFS(das_tank_inventories_daily!$M:$M,das_tank_inventories_daily!$C:$C,calculations!$B16,das_tank_inventories_daily!$H:$H,calculations!E$1) -> -27142.313 | F16: =+SUMIFS(das_tank_inventories_daily!$M:$M,das_tank_inventories_daily!$C:$C,calculations!$B16,das_tank_inventories_daily!$H:$H,calculations!F$1) -> -62362.065 | G16: =+SUMIFS(das_tank_inventories_daily!$M:$M,das_tank_inventories_daily!$C:$C,calculations!$B16,das_tank_inventories_daily!$H:$H,calculations!G$1) -> -15753.357 | H16: =+SUMIFS(das_tank_inventories_daily!$M:$M,das_tank_inventories_daily!$C:$C,calculations!$B16,das_tank_inventories_daily!$H:$H,calculations!H$1) -> 407830.76 | I16: =+SUMIFS(das_tank_inventories_daily!$M:$M,das_tank_inventories_daily!$C:$C,calculations!$B16,das_tank_inventories_daily!$H:$H,calculations!I$1) -> 317454.38 | J16: =+SUMIFS(das_tank_inventories_daily!$M:$M,das_tank_inventories_daily!$C:$C,calculations!$B16,das_tank_inventories_daily!$H:$H,calculations!J$1) -> -55218.495 | ... U16: =+SUMIFS(das_tank_inventories_daily!$M:$M,das_tank_inventories_daily!$C:$C,calculations!$B16,das_tank_inventories_daily!$H:$H,calculations!U$1) -> 384465.73 | W16: =+B16 -> 46038 | X16: =+SUMIFS(C16:U16,C16:U16,"<0") -> -740497.71 | Y16: =+SUMIFS(C16:U16,C16:U16,"<0") -> -740497.71 | Z16: =+Y16+X16 -> -1480995.4 | AB16: =+B16 -> 46038 | AC16: =+SUMIFS(C16:U16,C16:U16,"<0")/(AB16-AB13) -> -246832.57 | AD16: =+SUMIFS(C16:U16,C16:U16,">0")/(AB16-AB13) -> 621296.4 | AE16: =+AD16+AC16 -> 374463.83
AC17: =+SUMIFS(C17:U17,C17:U17,"<0")/(AB17-AB14) -> #DIV/0! | AD17: =+SUMIFS(C17:U17,C17:U17,">0")/(AB17-AB14) -> #DIV/0!
AC18: =+SUMIFS(C18:U18,C18:U18,"<0")/(AB18-AB15) -> #DIV/0! | AD18: =+SUMIFS(C18:U18,C18:U18,">0")/(AB18-AB15) -> #DIV/0!
B19: 46041 | C19: =+SUMIFS(das_tank_inventories_daily!$M:$M,das_tank_inventories_daily!$C:$C,calculations!$B19,das_tank_inventories_daily!$H:$H,calculations!C$1) -> 5829.502 | D19: =+SUMIFS(das_tank_inventories_daily!$M:$M,das_tank_inventories_daily!$C:$C,calculations!$B19,das_tank_inventories_daily!$H:$H,calculations!D$1) -> 5253.8772 | E19: =+SUMIFS(das_tank_inventories_daily!$M:$M,das_tank_inventories_daily!$C:$C,calculations!$B19,das_tank_inventories_daily!$H:$H,calculations!E$1) -> 28375.837 | F19: =+SUMIFS(das_tank_inventories_daily!$M:$M,das_tank_inventories_daily!$C:$C,calculations!$B19,das_tank_inventories_daily!$H:$H,calculations!F$1) -> -82697.036 | G19: =+SUMIFS(das_tank_inventories_daily!$M:$M,das_tank_inventories_daily!$C:$C,calculations!$B19,das_tank_inventories_daily!$H:$H,calculations!G$1) -> 18854.122 | H19: =+SUMIFS(das_tank_inventories_daily!$M:$M,das_tank_inventories_daily!$C:$C,calculations!$B19,das_tank_inventories_daily!$H:$H,calculations!H$1) -> 13954.186 | I19: =+SUMIFS(das_tank_inventories_daily!$M:$M,das_tank_inventories_daily!$C:$C,calculations!$B19,das_tank_inventories_daily!$H:$H,calculations!I$1) -> -473071.13 | J19: =+SUMIFS(das_tank_inventories_daily!$M:$M,das_tank_inventories_daily!$C:$C,calculations!$B19,das_tank_inventories_daily!$H:$H,calculations!J$1) -> -139516.26 | ... U19: =+SUMIFS(das_tank_inventories_daily!$M:$M,das_tank_inventories_daily!$C:$C,calculations!$B19,das_tank_inventories_daily!$H:$H,calculations!U$1) -> -391336.13 | W19: =+B19 -> 46041 | X19: =+SUMIFS(C19:U19,C19:U19,"<0") -> -2288252.3 | Y19: =+SUMIFS(C19:U19,C19:U19,"<0") -> -2288252.3 | Z19: =+Y19+X19 -> -4576504.6 | AB19: =+B19 -> 46041 | AC19: =+SUMIFS(C19:U19,C19:U19,"<0")/(AB19-AB16) -> -762750.77 | AD19: =+SUMIFS(C19:U19,C19:U19,">0")/(AB19-AB16) -> 108350.72 | AE19: =+AD19+AC19 -> -654400.04
AC20: =+SUMIFS(C20:U20,C20:U20,"<0")/(AB20-AB17) -> #DIV/0! | AD20: =+SUMIFS(C20:U20,C20:U20,">0")/(AB20-AB17) -> #DIV/0!
AC21: =+SUMIFS(C21:U21,C21:U21,"<0")/(AB21-AB18) -> #DIV/0! | AD21: =+SUMIFS(C21:U21,C21:U21,">0")/(AB21-AB18) -> #DIV/0!
AC22: =+SUMIFS(C22:U22,C22:U22,"<0")/(AB22-AB19) -> 0 | AD22: =+SUMIFS(C22:U22,C22:U22,">0")/(AB22-AB19) -> 0
AC23: =+SUMIFS(C23:U23,C23:U23,"<0")/(AB23-AB20) -> #DIV/0! | AD23: =+SUMIFS(C23:U23,C23:U23,">0")/(AB23-AB20) -> #DIV/0!
AC24: =+SUMIFS(C24:U24,C24:U24,"<0")/(AB24-AB21) -> #DIV/0! | AD24: =+SUMIFS(C24:U24,C24:U24,">0")/(AB24-AB21) -> #DIV/0!
B25: 46047 | C25: =+SUMIFS(das_tank_inventories_daily!$M:$M,das_tank_inventories_daily!$C:$C,calculations!$B25,das_tank_inventories_daily!$H:$H,calculations!C$1) -> -2717.0237 | D25: =+SUMIFS(das_tank_inventories_daily!$M:$M,das_tank_inventories_daily!$C:$C,calculations!$B25,das_tank_inventories_daily!$H:$H,calculations!D$1) -> -152.29302 | E25: =+SUMIFS(das_tank_inventories_daily!$M:$M,das_tank_inventories_daily!$C:$C,calculations!$B25,das_tank_inventories_daily!$H:$H,calculations!E$1) -> -2044.3967 | F25: =+SUMIFS(das_tank_inventories_daily!$M:$M,das_tank_inventories_daily!$C:$C,calculations!$B25,das_tank_inventories_daily!$H:$H,calculations!F$1) -> -135963.6 | G25: =+SUMIFS(das_tank_inventories_daily!$M:$M,das_tank_inventories_daily!$C:$C,calculations!$B25,das_tank_inventories_daily!$H:$H,calculations!G$1) -> -7433.6612 | H25: =+SUMIFS(das_tank_inventories_daily!$M:$M,das_tank_inventories_daily!$C:$C,calculations!$B25,das_tank_inventories_daily!$H:$H,calculations!H$1) -> -14745.852 | I25: =+SUMIFS(das_tank_inventories_daily!$M:$M,das_tank_inventories_daily!$C:$C,calculations!$B25,das_tank_inventories_daily!$H:$H,calculations!I$1) -> 43990.95 | J25: =+SUMIFS(das_tank_inventories_daily!$M:$M,das_tank_inventories_daily!$C:$C,calculations!$B25,das_tank_inventories_daily!$H:$H,calculations!J$1) -> 390653.07 | ... U25: =+SUMIFS(das_tank_inventories_daily!$M:$M,das_tank_inventories_daily!$C:$C,calculations!$B25,das_tank_inventories_daily!$H:$H,calculations!U$1) -> -31989.481 | W25: =+B25 -> 46047 | X25: =+SUMIFS(C25:U25,C25:U25,"<0") -> -925355.22 | Y25: =+SUMIFS(C25:U25,C25:U25,"<0") -> -925355.22 | Z25: =+Y25+X25 -> -1850710.4 | AB25: =+B25 -> 46047 | AC25: =+SUMIFS(C25:U25,C25:U25,"<0")/(AB25-AB22) -> -20.095885 | AD25: =+SUMIFS(C25:U25,C25:U25,">0")/(AB25-AB22) -> 22.0181 | AE25: =+AD25+AC25 -> 1.9222152
W26: =+#REF! -> #REF! | X26: =+SUMIFS(#REF!,#REF!,"<0") -> #REF! | Y26: =+SUMIFS(#REF!,#REF!,">0") -> #REF! | Z26: =+Y26+X26 -> #REF! | AC26: =+SUMIFS(C26:U26,C26:U26,"<0")/(AB26-AB23) -> #DIV/0! | AD26: =+SUMIFS(C26:U26,C26:U26,">0")/(AB26-AB23) -> #DIV/0!
W27: =+#REF! -> #REF! | X27: =+SUMIFS(#REF!,#REF!,"<0") -> #REF! | Y27: =+SUMIFS(#REF!,#REF!,">0") -> #REF! | Z27: =+Y27+X27 -> #REF! | AC27: =+SUMIFS(C27:U27,C27:U27,"<0")/(AB27-AB24) -> #DIV/0! | AD27: =+SUMIFS(C27:U27,C27:U27,">0")/(AB27-AB24) -> #DIV/0!
B28: 46050 | C28: =+SUMIFS(das_tank_inventories_daily!$M:$M,das_tank_inventories_daily!$C:$C,calculations!$B28,das_tank_inventories_daily!$H:$H,calculations!C$1) -> -2792.68 | D28: =+SUMIFS(das_tank_inventories_daily!$M:$M,das_tank_inventories_daily!$C:$C,calculations!$B28,das_tank_inventories_daily!$H:$H,calculations!D$1) -> -5443.8267 | E28: =+SUMIFS(das_tank_inventories_daily!$M:$M,das_tank_inventories_daily!$C:$C,calculations!$B28,das_tank_inventories_daily!$H:$H,calculations!E$1) -> -378551.22 | F28: =+SUMIFS(das_tank_inventories_daily!$M:$M,das_tank_inventories_daily!$C:$C,calculations!$B28,das_tank_inventories_daily!$H:$H,calculations!F$1) -> -9537.8367 | G28: =+SUMIFS(das_tank_inventories_daily!$M:$M,das_tank_inventories_daily!$C:$C,calculations!$B28,das_tank_inventories_daily!$H:$H,calculations!G$1) -> -7697.6319 | H28: =+SUMIFS(das_tank_inventories_daily!$M:$M,das_tank_inventories_daily!$C:$C,calculations!$B28,das_tank_inventories_daily!$H:$H,calculations!H$1) -> -440053.67 | I28: =+SUMIFS(das_tank_inventories_daily!$M:$M,das_tank_inventories_daily!$C:$C,calculations!$B28,das_tank_inventories_daily!$H:$H,calculations!I$1) -> -68856.283 | J28: =+SUMIFS(das_tank_inventories_daily!$M:$M,das_tank_inventories_daily!$C:$C,calculations!$B28,das_tank_inventories_daily!$H:$H,calculations!J$1) -> -6019.3852 | ... U28: =+SUMIFS(das_tank_inventories_daily!$M:$M,das_tank_inventories_daily!$C:$C,calculations!$B28,das_tank_inventories_daily!$H:$H,calculations!U$1) -> 424152 | W28: =+B28 -> 46050 | X28: =+SUMIFS(C28:U28,C28:U28,"<0") -> -950796.53 | Y28: =+SUMIFS(C28:U28,C28:U28,"<0") -> -950796.53 | Z28: =+Y28+X28 -> -1901593.1 | AB28: =+B28 -> 46050 | AC28: =+SUMIFS(C28:U28,C28:U28,"<0")/(AB28-AB25) -> -316932.18 | AD28: =+SUMIFS(C28:U28,C28:U28,">0")/(AB28-AB25) -> 466836.5 | AE28: =+AD28+AC28 -> 149904.33
W29: =+#REF! -> #REF! | X29: =+SUMIFS(#REF!,#REF!,"<0") -> #REF! | Y29: =+SUMIFS(#REF!,#REF!,">0") -> #REF! | Z29: =+Y29+X29 -> #REF! | AC29: =+SUMIFS(C29:U29,C29:U29,"<0")/(AB29-AB26) -> #DIV/0! | AD29: =+SUMIFS(C29:U29,C29:U29,">0")/(AB29-AB26) -> #DIV/0!
W30: =+#REF! -> #REF! | X30: =+SUMIFS(#REF!,#REF!,"<0") -> #REF! | Y30: =+SUMIFS(#REF!,#REF!,">0") -> #REF! | Z30: =+Y30+X30 -> #REF! | AC30: =+SUMIFS(C30:U30,C30:U30,"<0")/(AB30-AB27) -> #DIV/0! | AD30: =+SUMIFS(C30:U30,C30:U30,">0")/(AB30-AB27) -> #DIV/0! | AI30: 0 | AJ30: 0 | AK30: 0
B31: 46053 | C31: =+SUMIFS(das_tank_inventories_daily!$M:$M,das_tank_inventories_daily!$C:$C,calculations!$B31,das_tank_inventories_daily!$H:$H,calculations!C$1) -> 4478.103 | D31: =+SUMIFS(das_tank_inventories_daily!$M:$M,das_tank_inventories_daily!$C:$C,calculations!$B31,das_tank_inventories_daily!$H:$H,calculations!D$1) -> 5876.6817 | E31: =+SUMIFS(das_tank_inventories_daily!$M:$M,das_tank_inventories_daily!$C:$C,calculations!$B31,das_tank_inventories_daily!$H:$H,calculations!E$1) -> 25148.786 | F31: =+SUMIFS(das_tank_inventories_daily!$M:$M,das_tank_inventories_daily!$C:$C,calculations!$B31,das_tank_inventories_daily!$H:$H,calculations!F$1) -> 4582.9431 | G31: =+SUMIFS(das_tank_inventories_daily!$M:$M,das_tank_inventories_daily!$C:$C,calculations!$B31,das_tank_inventories_daily!$H:$H,calculations!G$1) -> 12450.831 | H31: =+SUMIFS(das_tank_inventories_daily!$M:$M,das_tank_inventories_daily!$C:$C,calculations!$B31,das_tank_inventories_daily!$H:$H,calculations!H$1) -> 393018.77 | I31: =+SUMIFS(das_tank_inventories_daily!$M:$M,das_tank_inventories_daily!$C:$C,calculations!$B31,das_tank_inventories_daily!$H:$H,calculations!I$1) -> 504014.67 | J31: =+SUMIFS(das_tank_inventories_daily!$M:$M,das_tank_inventories_daily!$C:$C,calculations!$B31,das_tank_inventories_daily!$H:$H,calculations!J$1) -> -384633.68 | ... U31: =+SUMIFS(das_tank_inventories_daily!$M:$M,das_tank_inventories_daily!$C:$C,calculations!$B31,das_tank_inventories_daily!$H:$H,calculations!U$1) -> -75926.454 | W31: =+B31 -> 46053 | X31: =+SUMIFS(C31:U31,C31:U31,"<0") -> -1925909.9 | Y31: =+SUMIFS(C31:U31,C31:U31,"<0") -> -1925909.9 | Z31: =+Y31+X31 -> -3851819.7 | AB31: =+B31 -> 46053 | AC31: =+SUMIFS(C31:U31,C31:U31,"<0")/(AB31-AB28) -> -641969.95 | AD31: =+SUMIFS(C31:U31,C31:U31,">0")/(AB31-AB28) -> 477958.83 | AE31: =+AD31+AC31 -> -164011.13 | AH31: =+AB31 -> 46053 | AI31: =+AI30+AC31 -> -641969.95 | AJ31: =+AJ30+AD31 -> 477958.83 | AK31: =+AK30+AE31 -> -164011.13
W32: =+#REF! -> #REF! | X32: =+SUMIFS(#REF!,#REF!,"<0") -> #REF! | Y32: =+SUMIFS(#REF!,#REF!,">0") -> #REF! | Z32: =+Y32+X32 -> #REF! | AC32: =+SUMIFS(C32:U32,C32:U32,"<0")/(AB32-AB29) -> #DIV/0! | AD32: =+SUMIFS(C32:U32,C32:U32,">0")/(AB32-AB29) -> #DIV/0! | AH32: =+AB32 -> 0 | AI32: =+AI31+AC32 -> #DIV/0! | AJ32: =+AJ31+AD32 -> #DIV/0! | AK32: =+AK31+AE32 -> -164011.13
W33: =+#REF! -> #REF! | X33: =+SUMIFS(#REF!,#REF!,"<0") -> #REF! | Y33: =+SUMIFS(#REF!,#REF!,">0") -> #REF! | Z33: =+Y33+X33 -> #REF! | AC33: =+SUMIFS(C33:U33,C33:U33,"<0")/(AB33-AB30) -> #DIV/0! | AD33: =+SUMIFS(C33:U33,C33:U33,">0")/(AB33-AB30) -> #DIV/0! | AH33: =+AB33 -> 0 | AI33: =+AI32+AC33 -> #DIV/0! | AJ33: =+AJ32+AD33 -> #DIV/0! | AK33: =+AK32+AE33 -> -164011.13
B34: 46056 | C34: =+SUMIFS(das_tank_inventories_daily!$M:$M,das_tank_inventories_daily!$C:$C,calculations!$B34,das_tank_inventories_daily!$H:$H,calculations!C$1) -> -4348.7939 | D34: =+SUMIFS(das_tank_inventories_daily!$M:$M,das_tank_inventories_daily!$C:$C,calculations!$B34,das_tank_inventories_daily!$H:$H,calculations!D$1) -> -9004.1207 | E34: =+SUMIFS(das_tank_inventories_daily!$M:$M,das_tank_inventories_daily!$C:$C,calculations!$B34,das_tank_inventories_daily!$H:$H,calculations!E$1) -> 325769.97 | F34: =+SUMIFS(das_tank_inventories_daily!$M:$M,das_tank_inventories_daily!$C:$C,calculations!$B34,das_tank_inventories_daily!$H:$H,calculations!F$1) -> -36895.707 | G34: =+SUMIFS(das_tank_inventories_daily!$M:$M,das_tank_inventories_daily!$C:$C,calculations!$B34,das_tank_inventories_daily!$H:$H,calculations!G$1) -> -14859.301 | H34: =+SUMIFS(das_tank_inventories_daily!$M:$M,das_tank_inventories_daily!$C:$C,calculations!$B34,das_tank_inventories_daily!$H:$H,calculations!H$1) -> 12350.237 | I34: =+SUMIFS(das_tank_inventories_daily!$M:$M,das_tank_inventories_daily!$C:$C,calculations!$B34,das_tank_inventories_daily!$H:$H,calculations!I$1) -> -421937.83 | J34: =+SUMIFS(das_tank_inventories_daily!$M:$M,das_tank_inventories_daily!$C:$C,calculations!$B34,das_tank_inventories_daily!$H:$H,calculations!J$1) -> 398538.77 | ... U34: =+SUMIFS(das_tank_inventories_daily!$M:$M,das_tank_inventories_daily!$C:$C,calculations!$B34,das_tank_inventories_daily!$H:$H,calculations!U$1) -> -36203.852 | W34: =+B34 -> 46056 | X34: =+SUMIFS(C34:U34,C34:U34,"<0") -> -1563606.6 | Y34: =+SUMIFS(C34:U34,C34:U34,"<0") -> -1563606.6 | Z34: =+Y34+X34 -> -3127213.1 | AB34: =+B34 -> 46056 | AC34: =+SUMIFS(C34:U34,C34:U34,"<0")/(AB34-AB31) -> -521202.19 | AD34: =+SUMIFS(C34:U34,C34:U34,">0")/(AB34-AB31) -> 781286.04 | AE34: =+AD34+AC34 -> 260083.85 | AH34: =+AB34 -> 46056 | AI34: =+AI31+AC34 -> -1163172.1 | AJ34: =+AJ33+AD34 -> #DIV/0! | AK34: =+AK33+AE34 -> 96072.721
W35: =+#REF! -> #REF! | X35: =+SUMIFS(#REF!,#REF!,"<0") -> #REF! | Y35: =+SUMIFS(#REF!,#REF!,">0") -> #REF! | Z35: =+Y35+X35 -> #REF! | AC35: =+SUMIFS(C35:U35,C35:U35,"<0")/(AB35-AB32) -> #DIV/0! | AD35: =+SUMIFS(C35:U35,C35:U35,">0")/(AB35-AB32) -> #DIV/0! | AH35: =+AB35 -> 0 | AI35: =+AI34+AC35 -> #DIV/0! | AJ35: =+AJ34+AD35 -> #DIV/0! | AK35: =+AK34+AE35 -> 96072.721
W36: =+#REF! -> #REF! | X36: =+SUMIFS(#REF!,#REF!,"<0") -> #REF! | Y36: =+SUMIFS(#REF!,#REF!,">0") -> #REF! | Z36: =+Y36+X36 -> #REF! | AC36: =+SUMIFS(C36:U36,C36:U36,"<0")/(AB36-AB33) -> #DIV/0! | AD36: =+SUMIFS(C36:U36,C36:U36,">0")/(AB36-AB33) -> #DIV/0! | AH36: =+AB36 -> 0 | AI36: =+AI35+AC36 -> #DIV/0! | AJ36: =+AJ35+AD36 -> #DIV/0! | AK36: =+AK35+AE36 -> 96072.721
B37: 46059 | C37: =+SUMIFS(das_tank_inventories_daily!$M:$M,das_tank_inventories_daily!$C:$C,calculations!$B37,das_tank_inventories_daily!$H:$H,calculations!C$1) -> 3613.3655 | D37: =+SUMIFS(das_tank_inventories_daily!$M:$M,das_tank_inventories_daily!$C:$C,calculations!$B37,das_tank_inventories_daily!$H:$H,calculations!D$1) -> 10403.858 | E37: =+SUMIFS(das_tank_inventories_daily!$M:$M,das_tank_inventories_daily!$C:$C,calculations!$B37,das_tank_inventories_daily!$H:$H,calculations!E$1) -> 33547.41 | F37: =+SUMIFS(das_tank_inventories_daily!$M:$M,das_tank_inventories_daily!$C:$C,calculations!$B37,das_tank_inventories_daily!$H:$H,calculations!F$1) -> 52726.408 | G37: =+SUMIFS(das_tank_inventories_daily!$M:$M,das_tank_inventories_daily!$C:$C,calculations!$B37,das_tank_inventories_daily!$H:$H,calculations!G$1) -> 15797.642 | H37: =+SUMIFS(das_tank_inventories_daily!$M:$M,das_tank_inventories_daily!$C:$C,calculations!$B37,das_tank_inventories_daily!$H:$H,calculations!H$1) -> -390363.07 | I37: =+SUMIFS(das_tank_inventories_daily!$M:$M,das_tank_inventories_daily!$C:$C,calculations!$B37,das_tank_inventories_daily!$H:$H,calculations!I$1) -> 364652.35 | J37: =+SUMIFS(das_tank_inventories_daily!$M:$M,das_tank_inventories_daily!$C:$C,calculations!$B37,das_tank_inventories_daily!$H:$H,calculations!J$1) -> -318782.38 | ... U37: =+SUMIFS(das_tank_inventories_daily!$M:$M,das_tank_inventories_daily!$C:$C,calculations!$B37,das_tank_inventories_daily!$H:$H,calculations!U$1) -> -19475.044 | W37: =+B37 -> 46059 | X37: =+SUMIFS(C37:U37,C37:U37,"<0") -> -1915287.8 | Y37: =+SUMIFS(C37:U37,C37:U37,"<0") -> -1915287.8 | Z37: =+Y37+X37 -> -3830575.6 | AB37: =+B37 -> 46059 | AC37: =+SUMIFS(C37:U37,C37:U37,"<0")/(AB37-AB34) -> -638429.27 | AD37: =+SUMIFS(C37:U37,C37:U37,">0")/(AB37-AB34) -> 474786.73 | AE37: =+AD37+AC37 -> -163642.54 | AH37: =+AB37 -> 46059 | AI37: =+AI36+AC37 -> #DIV/0! | AJ37: =+AJ36+AD37 -> #DIV/0! | AK37: =+AK36+AE37 -> -67569.824
W38: =+#REF! -> #REF! | X38: =+SUMIFS(#REF!,#REF!,"<0") -> #REF! | Y38: =+SUMIFS(#REF!,#REF!,">0") -> #REF! | Z38: =+Y38+X38 -> #REF! | AC38: =+SUMIFS(C38:U38,C38:U38,"<0")/(AB38-AB35) -> #DIV/0! | AD38: =+SUMIFS(C38:U38,C38:U38,">0")/(AB38-AB35) -> #DIV/0! | AH38: =+AB38 -> 0 | AI38: =+AI37+AC38 -> #DIV/0! | AJ38: =+AJ37+AD38 -> #DIV/0! | AK38: =+AK37+AE38 -> -67569.824
W39: =+#REF! -> #REF! | X39: =+SUMIFS(#REF!,#REF!,"<0") -> #REF! | Y39: =+SUMIFS(#REF!,#REF!,">0") -> #REF! | Z39: =+Y39+X39 -> #REF! | AC39: =+SUMIFS(C39:U39,C39:U39,"<0")/(AB39-AB36) -> #DIV/0! | AD39: =+SUMIFS(C39:U39,C39:U39,">0")/(AB39-AB36) -> #DIV/0! | AH39: =+AB39 -> 0 | AI39: =+AI38+AC39 -> #DIV/0! | AJ39: =+AJ38+AD39 -> #DIV/0! | AK39: =+AK38+AE39 -> -67569.824
B40: 46062 | C40: =+SUMIFS(das_tank_inventories_daily!$M:$M,das_tank_inventories_daily!$C:$C,calculations!$B40,das_tank_inventories_daily!$H:$H,calculations!C$1) -> -4350.2358 | D40: =+SUMIFS(das_tank_inventories_daily!$M:$M,das_tank_inventories_daily!$C:$C,calculations!$B40,das_tank_inventories_daily!$H:$H,calculations!D$1) -> -6689.9289 | E40: =+SUMIFS(das_tank_inventories_daily!$M:$M,das_tank_inventories_daily!$C:$C,calculations!$B40,das_tank_inventories_daily!$H:$H,calculations!E$1) -> -31610.13 | F40: =+SUMIFS(das_tank_inventories_daily!$M:$M,das_tank_inventories_daily!$C:$C,calculations!$B40,das_tank_inventories_daily!$H:$H,calculations!F$1) -> 427658.78 | G40: =+SUMIFS(das_tank_inventories_daily!$M:$M,das_tank_inventories_daily!$C:$C,calculations!$B40,das_tank_inventories_daily!$H:$H,calculations!G$1) -> -14700.464 | H40: =+SUMIFS(das_tank_inventories_daily!$M:$M,das_tank_inventories_daily!$C:$C,calculations!$B40,das_tank_inventories_daily!$H:$H,calculations!H$1) -> 481425.31 | I40: =+SUMIFS(das_tank_inventories_daily!$M:$M,das_tank_inventories_daily!$C:$C,calculations!$B40,das_tank_inventories_daily!$H:$H,calculations!I$1) -> 75680.99 | J40: =+SUMIFS(das_tank_inventories_daily!$M:$M,das_tank_inventories_daily!$C:$C,calculations!$B40,das_tank_inventories_daily!$H:$H,calculations!J$1) -> -66604.254 | ... U40: =+SUMIFS(das_tank_inventories_daily!$M:$M,das_tank_inventories_daily!$C:$C,calculations!$B40,das_tank_inventories_daily!$H:$H,calculations!U$1) -> -195147.75 | W40: =+B40 -> 46062 | X40: =+SUMIFS(C40:U40,C40:U40,"<0") -> -1527739.8 | Y40: =+SUMIFS(C40:U40,C40:U40,"<0") -> -1527739.8 | Z40: =+Y40+X40 -> -3055479.7 | AB40: =+B40 -> 46062 | AC40: =+SUMIFS(C40:U40,C40:U40,"<0")/(AB40-AB37) -> -509246.62 | AD40: =+SUMIFS(C40:U40,C40:U40,">0")/(AB40-AB37) -> 670273.21 | AE40: =+AD40+AC40 -> 161026.59 | AH40: =+AB40 -> 46062 | AI40: =+AI39+AC40 -> #DIV/0! | AJ40: =+AJ39+AD40 -> #DIV/0! | AK40: =+AK39+AE40 -> 93456.769
W41: =+#REF! -> #REF! | X41: =+SUMIFS(#REF!,#REF!,"<0") -> #REF! | Y41: =+SUMIFS(#REF!,#REF!,">0") -> #REF! | Z41: =+Y41+X41 -> #REF! | AC41: =+SUMIFS(C41:U41,C41:U41,"<0")/(AB41-AB38) -> #DIV/0! | AD41: =+SUMIFS(C41:U41,C41:U41,">0")/(AB41-AB38) -> #DIV/0! | AH41: =+AB41 -> 0 | AI41: =+AI40+AC41 -> #DIV/0! | AJ41: =+AJ40+AD41 -> #DIV/0! | AK41: =+AK40+AE41 -> 93456.769
W42: =+#REF! -> #REF! | X42: =+SUMIFS(#REF!,#REF!,"<0") -> #REF! | Y42: =+SUMIFS(#REF!,#REF!,">0") -> #REF! | Z42: =+Y42+X42 -> #REF! | AC42: =+SUMIFS(C42:U42,C42:U42,"<0")/(AB42-AB39) -> #DIV/0! | AD42: =+SUMIFS(C42:U42,C42:U42,">0")/(AB42-AB39) -> #DIV/0! | AH42: =+AB42 -> 0 | AI42: =+AI41+AC42 -> #DIV/0! | AJ42: =+AJ41+AD42 -> #DIV/0! | AK42: =+AK41+AE42 -> 93456.769
B43: 46065 | C43: =+SUMIFS(das_tank_inventories_daily!$M:$M,das_tank_inventories_daily!$C:$C,calculations!$B43,das_tank_inventories_daily!$H:$H,calculations!C$1) -> 3914.2189 | D43: =+SUMIFS(das_tank_inventories_daily!$M:$M,das_tank_inventories_daily!$C:$C,calculations!$B43,das_tank_inventories_daily!$H:$H,calculations!D$1) -> 4915.5299 | E43: =+SUMIFS(das_tank_inventories_daily!$M:$M,das_tank_inventories_daily!$C:$C,calculations!$B43,das_tank_inventories_daily!$H:$H,calculations!E$1) -> -272031.24 | F43: =+SUMIFS(das_tank_inventories_daily!$M:$M,das_tank_inventories_daily!$C:$C,calculations!$B43,das_tank_inventories_daily!$H:$H,calculations!F$1) -> -516.80977 | G43: =+SUMIFS(das_tank_inventories_daily!$M:$M,das_tank_inventories_daily!$C:$C,calculations!$B43,das_tank_inventories_daily!$H:$H,calculations!G$1) -> 12340.434 | H43: =+SUMIFS(das_tank_inventories_daily!$M:$M,das_tank_inventories_daily!$C:$C,calculations!$B43,das_tank_inventories_daily!$H:$H,calculations!H$1) -> -481434.41 | I43: =+SUMIFS(das_tank_inventories_daily!$M:$M,das_tank_inventories_daily!$C:$C,calculations!$B43,das_tank_inventories_daily!$H:$H,calculations!I$1) -> -229183.28 | J43: =+SUMIFS(das_tank_inventories_daily!$M:$M,das_tank_inventories_daily!$C:$C,calculations!$B43,das_tank_inventories_daily!$H:$H,calculations!J$1) -> 303319.04 | ... U43: =+SUMIFS(das_tank_inventories_daily!$M:$M,das_tank_inventories_daily!$C:$C,calculations!$B43,das_tank_inventories_daily!$H:$H,calculations!U$1) -> -73190.873 | W43: =+B43 -> 46065 | X43: =+SUMIFS(C43:U43,C43:U43,"<0") -> -1529327.3 | Y43: =+SUMIFS(C43:U43,C43:U43,"<0") -> -1529327.3 | Z43: =+Y43+X43 -> -3058654.7 | AB43: =+B43 -> 46065 | AC43: =+SUMIFS(C43:U43,C43:U43,"<0")/(AB43-AB40) -> -509775.78 | AD43: =+SUMIFS(C43:U43,C43:U43,">0")/(AB43-AB40) -> 557074.77 | AE43: =+AD43+AC43 -> 47298.986 | AH43: =+AB43 -> 46065 | AI43: =+AI42+AC43 -> #DIV/0! | AJ43: =+AJ42+AD43 -> #DIV/0! | AK43: =+AK42+AE43 -> 140755.76
W44: =+#REF! -> #REF! | X44: =+SUMIFS(#REF!,#REF!,"<0") -> #REF! | Y44: =+SUMIFS(#REF!,#REF!,">0") -> #REF! | Z44: =+Y44+X44 -> #REF! | AC44: =+SUMIFS(C44:U44,C44:U44,"<0")/(AB44-AB41) -> #DIV/0! | AD44: =+SUMIFS(C44:U44,C44:U44,">0")/(AB44-AB41) -> #DIV/0! | AH44: =+AB44 -> 0 | AI44: =+AI43+AC44 -> #DIV/0! | AJ44: =+AJ43+AD44 -> #DIV/0! | AK44: =+AK43+AE44 -> 140755.76
...

Sheet table_compare
C1: Date | D1: tank_draw | E1: tank_draw_kb | F1: tanker_tracking_kb
C2: 46026 | D2: -1209323.7 | E2: =D2/1000 -> -1209.3237
C3: 46029 | D3: -2238216.8 | E3: =D3/1000 -> -2238.2168
C4: 46032 | D4: -630031.27 | E4: =D4/1000 -> -630.03127
C5: 46035 | D5: -1523795.3 | E5: =D5/1000 -> -1523.7953
C6: 46038 | D6: -740497.71 | E6: =D6/1000 -> -740.49771
C7: 46041 | D7: -2288252.3 | E7: =D7/1000 -> -2288.2523
C8: 46047 | D8: -925355.22 | E8: =D8/1000 -> -925.35522
C9: 46050 | D9: -950796.53 | E9: =D9/1000 -> -950.79653
C10: 46053 | D10: -1925909.9 | E10: =D10/1000 -> -1925.9099
C11: 46056 | D11: -1563606.6 | E11: =D11/1000 -> -1563.6066
C12: 46059 | D12: -1915287.8 | E12: =D12/1000 -> -1915.2878
C13: 46062 | D13: -1527739.8 | E13: =D13/1000 -> -1527.7398
... C71: 46225 | D71: -971435.3 | E71: =D71/1000 -> -971.4353
C72: 46228 | D72: -1047554.7 | E72: =D72/1000 -> -1047.5547 | G72: -750
C73: 46231 | D73: -1298326.1 | E73: =D73/1000 -> -1298.3261 | G73: 0
C74: 46234 | D74: -212015.52 | E74: =D74/1000 -> -212.01552 | G74: -2000
C75: 46237 | D75: -806644.23 | E75: =D75/1000 -> -806.64423 | G75: -4000
C76: 46240 | D76: -1368725.9 | E76: =D76/1000 -> -1368.7259 | G76: -2000
C77: 46243 | D77: -1701225.1 | E77: =D77/1000 -> -1701.2251 | G77: 0
C78: 46246 | D78: -2103102.1 | E78: =D78/1000 -> -2103.1021 | G78: -2000
